Workbook

Sheet README
A1: Title of the article: "Metals for the Energy Transition: A Heavy Environmental Burden to Life?"
A2: Authors: Anne de Bortoli, Marin Pellan, Marguerite Fauroux
A3: Affiliations:
A4: Journal: Joule
A7: TAB_NAME | B7: DESCRIPTION | C7: SOURCE
A8: calculation
A9: data_availability | B9: Recap of data availability for USGS (Mineral Commodities Summary and Mineral Yearbook) and World Mining Data. See the 'Minerals_data' notebook for data treatment. | C9: -
A10: MYB | B10: Manual collection of data for the relevant metals, for the latest year available | C10: https://www.usgs.gov/centers/national-minerals-information-center/minerals-yearbook-metals-and-minerals
A11: MCS | B11: Manual collection of data for the relevant metals from MCS2022 to MCS2025. Note: for silicon, MCS2023 and MCS2023 only provide the combined totals for ferrosilicon and silicon metal. | C11: https://www.usgs.gov/centers/national-minerals-information-center/mineral-commodity-summaries
A12: Lundaev | B12: 2020 production given in the SI. It is used to decompose the PGM and REEs production data. | C12: Lundaev, Vitalii, A.A. Solomon, Tien Le, Alena Lohrmann, and Christian Breyer. 2023. “Review of Critical Materials for the Energy Transition, an Analysis of Global Resources and Production Databases and the State of Material Circularity.” Minerals Engineering 203 (November):108282. https://doi.org/10.1016/j.mineng.2023.108282.
A13: ChartierPoncelet | B13: Data process yields given in the SI. The production yield is used to convert mine production to refinery production. | C13: Charpentier Poncelet, Alexandre, Christoph Helbig, Philippe Loubet, Antoine Beylot, Stéphanie Muller, Jacques Villeneuve, Bertrand Laratte, Andrea Thorenz, Axel Tuma, and Guido Sonnemann. 2022. “Losses and Lifetimes of Metals in the Economy.” Nature Sustainability 5 (8): 717–26. https://doi.org/10.1038/s41893-022-00895-8.
A14: IEA_secondary_prod | B14: Share of secondary supply in total demand for selected materials in the NZS | C14: https://www.iea.org/data-and-statistics/charts/share-of-secondary-supply-in-total-demand-for-selected-materials-in-the-net-zero-scenario-2010-2040
A15: Additional_resources

Sheet for_pandas
A1: =CALCULATION!A1 -> Z | B1: =CALCULATION!B1 -> Symbol | C1: =CALCULATION!C1 -> Metal | D1: Refined_primary_production | E1: Secondary_production | F1: =CALCULATION!K1 -> Total_refinery_production | G1: =CALCULATION!L1 -> Unit | H1: =CALCULATION!M1 -> Year
A2: =CALCULATION!A2 -> 13 | B2: =CALCULATION!B2 -> Al | C2: =CALCULATION!C2 -> Aluminium | D2: =CALCULATION!J2 -> 70000 | E2: =CALCULATION!H2 -> 41111.111 | F2: =CALCULATION!K2 -> 111111.11 | G2: =CALCULATION!L2 -> kt | H2: =CALCULATION!M2 -> 2023
A3: =CALCULATION!A3 -> 33 | B3: =CALCULATION!B3 -> As | C3: =CALCULATION!C3 -> Arsenic | D3: =CALCULATION!J3 -> 61500 | E3: =CALCULATION!H3 -> 0 | F3: =CALCULATION!K3 -> 61500 | G3: =CALCULATION!L3 -> t | H3: =CALCULATION!M3 -> 2023
A4: =CALCULATION!A4 -> 5 | B4: =CALCULATION!B4 -> B | C4: =CALCULATION!C4 -> Boron | D4: =CALCULATION!J4 -> 3055.888 | E4: =CALCULATION!H4 -> 0 | F4: =CALCULATION!K4 -> 3055.888 | G4: =CALCULATION!L4 -> kt | H4: =CALCULATION!M4 -> 2023
A5: =CALCULATION!A5 -> 48 | B5: =CALCULATION!B5 -> Cd | C5: =CALCULATION!C5 -> Cadmium | D5: =CALCULATION!J5 -> 24100 | E5: =CALCULATION!H5 -> 0 | F5: =CALCULATION!K5 -> 24100 | G5: =CALCULATION!L5 -> t | H5: =CALCULATION!M5 -> 2023
A6: =CALCULATION!A6 -> 24 | B6: =CALCULATION!B6 -> Cr | C6: =CALCULATION!C6 -> Chromium | D6: =CALCULATION!J6 -> 15700 | E6: =CALCULATION!H6 -> 0 | F6: =CALCULATION!K6 -> 15700 | G6: =CALCULATION!L6 -> kt | H6: =CALCULATION!M6 -> 2023
A7: =CALCULATION!A7 -> 27 | B7: =CALCULATION!B7 -> Co | C7: =CALCULATION!C7 -> Cobalt | D7: =CALCULATION!J7 -> 180000 | E7: =CALCULATION!H7 -> 20000 | F7: =CALCULATION!K7 -> 200000 | G7: =CALCULATION!L7 -> t | H7: =CALCULATION!M7 -> 2023
A8: =CALCULATION!A8 -> 29 | B8: =CALCULATION!B8 -> Cu | C8: =CALCULATION!C8 -> Copper | D8: =CALCULATION!J8 -> 22712.4 | E8: =CALCULATION!H8 -> 4287.6 | F8: =CALCULATION!K8 -> 27000 | G8: =CALCULATION!L8 -> kt | H8: =CALCULATION!M8 -> 2023
A9: =CALCULATION!A9 -> 66 | B9: =CALCULATION!B9 -> Dy | C9: =CALCULATION!C9 -> Dysprosium | D9: =CALCULATION!J9 -> 1376.9589 | E9: =CALCULATION!H9 -> 0 | F9: =CALCULATION!K9 -> 1376.9589 | G9: =CALCULATION!L9 -> t | H9: =CALCULATION!M9 -> 2023
A10: =CALCULATION!A12 -> 31 | B10: =CALCULATION!B12 -> Ga | C10: =CALCULATION!C12 -> Gallium | D10: =CALCULATION!J12 -> 633000 | E10: =CALCULATION!H12 -> 0 | F10: =CALCULATION!K12 -> 633000 | G10: =CALCULATION!L12 -> kg | H10: =CALCULATION!M12 -> 2023
A11: =CALCULATION!A13 -> - | B11: C | C11: =CALCULATION!C13 -> Graphite | D11: =CALCULATION!J13 -> 1530000 | E11: =CALCULATION!H13 -> 0 | F11: =CALCULATION!K13 -> 1530000 | G11: =CALCULATION!L13 -> t | H11: =CALCULATION!M13 -> 2023
A12: =CALCULATION!A15 -> 49 | B12: =CALCULATION!B15 -> In | C12: =CALCULATION!C15 -> Indium | D12: =CALCULATION!J15 -> 1020 | E12: =CALCULATION!H15 -> 0 | F12: =CALCULATION!K15 -> 1020 | G12: =CALCULATION!L15 -> t | H12: =CALCULATION!M15 -> 2023
A13: =CALCULATION!A16 -> 77 | B13: =CALCULATION!B16 -> Ir | C13: =CALCULATION!C16 -> Iridium | D13: =CALCULATION!J16 -> 1954.6385 | E13: =CALCULATION!H16 -> 0 | F13: =CALCULATION!K16 -> 1954.6385 | G13: =CALCULATION!L16 -> kg | H13: =CALCULATION!M16 -> 2023
A14: =CALCULATION!A17 -> 57 | B14: =CALCULATION!B17 -> La | C14: =CALCULATION!C17 -> Lanthanum | D14: =CALCULATION!J17 -> 59731.313 | E14: =CALCULATION!H17 -> 0 | F14: =CALCULATION!K17 -> 59731.313 | G14: =CALCULATION!L17 -> t | H14: =CALCULATION!M17 -> 2023
A15: =CALCULATION!A18 -> 82 | B15: =CALCULATION!B18 -> Pb | C15: =CALCULATION!C18 -> Lead | D15: =CALCULATION!J18 -> 4164237.7 | E15: =CALCULATION!H18 -> 7280067.3 | F15: =CALCULATION!K18 -> 11444305 | G15: =CALCULATION!L18 -> kt | H15: =CALCULATION!M18 -> 2023
A16: =CALCULATION!A19 -> 3 | B16: =CALCULATION!B19 -> Li | C16: =CALCULATION!C19 -> Lithium | D16: =CALCULATION!J19 -> 142630.78 | E16: =CALCULATION!H19 -> 6309.2784 | F16: =CALCULATION!K19 -> 148940.05 | G16: =CALCULATION!L19 -> t | H16: =CALCULATION!M19 -> 2023
A17: =CALCULATION!A20 -> 12 | B17: =CALCULATION!B20 -> Mg | C17: =CALCULATION!C20 -> Magnesium | D17: =CALCULATION!J20 -> 900 | E17: =CALCULATION!H20 -> 0 | F17: =CALCULATION!K20 -> 900 | G17: =CALCULATION!L20 -> kt | H17: =CALCULATION!M20 -> 2023
A18: =CALCULATION!A21 -> 25 | B18: =CALCULATION!B21 -> Mn | C18: =CALCULATION!C21 -> Manganese | D18: =CALCULATION!J21 -> 13720 | E18: =CALCULATION!H21 -> 0 | F18: =CALCULATION!K21 -> 13720 | G18: =CALCULATION!L21 -> kt | H18: =CALCULATION!M21 -> 2023
A19: =CALCULATION!A22 -> 42 | B19: =CALCULATION!B22 -> Mo | C19: =CALCULATION!C22 -> Molybdenum | D19: =CALCULATION!J22 -> 148800 | E19: =CALCULATION!H22 -> 0 | F19: =CALCULATION!K22 -> 148800 | G19: =CALCULATION!L22 -> t | H19: =CALCULATION!M22 -> 2023
A20: =CALCULATION!A23 -> 60 | B20: =CALCULATION!B23 -> Nd | C20: =CALCULATION!C23 -> Neodymium | D20: =CALCULATION!J23 -> 37816.884 | E20: =CALCULATION!H23 -> 0 | F20: =CALCULATION!K23 -> 37816.884 | G20: =CALCULATION!L23 -> t | H20: =CALCULATION!M23 -> 2023
A21: =CALCULATION!A24 -> 28 | B21: =CALCULATION!B24 -> Ni | C21: =CALCULATION!C24 -> Nickel | D21: =CALCULATION!J24 -> 3516483.5 | E21: =CALCULATION!H24 -> 35520.036 | F21: =CALCULATION!K24 -> 3552003.6 | G21: =CALCULATION!L24 -> t | H21: =CALCULATION!M24 -> 2023
A22: =CALCULATION!A25 -> 41 | B22: =CALCULATION!B25 -> Nb | C22: =CALCULATION!C25 -> Niobium | D22: =CALCULATION!J25 -> 78100 | E22: =CALCULATION!H25 -> 0 | F22: =CALCULATION!K25 -> 78100 | G22: =CALCULATION!L25 -> t | H22: =CALCULATION!M25 -> 2023
A23: =CALCULATION!A26 -> - | B23: =CALCULATION!B26 -> - | C23: =CALCULATION!C26 -> PGMs | D23: =CALCULATION!J26 -> 117249.15 | E23: =CALCULATION!H26 -> 0 | F23: =CALCULATION!K26 -> 117249.15 | G23: =CALCULATION!L26 -> kg | H23: =CALCULATION!M26 -> 2023
... A37: =CALCULATION!A40 -> 40 | B37: =CALCULATION!B40 -> Zr | C37: =CALCULATION!C40 -> Zirconium | D37: =CALCULATION!J40 -> 1231.2 | E37: =CALCULATION!H40 -> 0 | F37: =CALCULATION!K40 -> 1231.2 | G37: =CALCULATION!L40 -> kt | H37: =CALCULATION!M40 -> 2023

Sheet for_pandas_sec
A1: Metal | B1: 2018 | C1: 2019 | D1: 2020 | E1: 2021 | F1: 2022 | G1: 2023 | H1: 2024 | I1: 2025 | J1: 2026 | K1: 2027 | L1: 2028 | M1: 2029 | N1: 2030 | O1: 2031 | P1: 2032 | Q1: 2033 | R1: 2034 | S1: 2035 | T1: 2036 | U1: 2037 | V1: 2038 | W1: 2039 | X1: 2040
A2: Aluminium | B2: 0.35 | C2: 0.35 | D2: 0.35 | E2: 0.36 | F2: 0.36 | G2: 0.37 | H2: 0.38 | I2: 0.39 | J2: 0.39 | K2: 0.4 | L2: 0.41 | M2: 0.41 | N2: 0.42 | O2: 0.42 | P2: 0.43 | Q2: 0.43 | R2: 0.44 | S2: 0.44 | T2: 0.45 | U2: 0.46 | V2: 0.46 | W2: 0.47 | X2: 0.47
A3: Cobalt | B3: 0.06 | C3: 0.07 | D3: 0.07 | E3: 0.08 | F3: 0.09 | G3: 0.1 | H3: 0.11 | I3: 0.11 | J3: 0.11 | K3: 0.12 | L3: 0.12 | M3: 0.12 | N3: 0.12 | O3: 0.13 | P3: 0.14 | Q3: 0.15 | R3: 0.16 | S3: 0.18 | T3: 0.19 | U3: 0.21 | V3: 0.24 | W3: 0.26 | X3: 0.29
A4: Copper | B4: 0.17 | C4: 0.17 | D4: 0.17 | E4: 0.17 | F4: 0.17 | G4: 0.17 | H4: 0.17 | I4: 0.17 | J4: 0.17 | K4: 0.17 | L4: 0.17 | M4: 0.17 | N4: 0.18 | O4: 0.18 | P4: 0.19 | Q4: 0.2 | R4: 0.21 | S4: 0.22 | T4: 0.23 | U4: 0.24 | V4: 0.26 | W4: 0.27 | X4: 0.28
A5: Lithium | B5: 0.01 | C5: 0.01 | D5: 0.01 | E5: 0.01 | F5: 0.02 | G5: 0.03 | H5: 0.06 | I5: 0.06 | J5: 0.06 | K5: 0.06 | L5: 0.05 | M5: 0.05 | N5: 0.05 | O5: 0.05 | P5: 0.05 | Q5: 0.06 | R5: 0.06 | S5: 0.07 | T5: 0.07 | U5: 0.08 | V5: 0.09 | W5: 0.1 | X5: 0.12
A6: Nickel | B6: 0 | C6: 0 | D6: 0 | E6: 0 | F6: 0.01 | G6: 0.01 | H6: 0.02 | I6: 0.02 | J6: 0.02 | K6: 0.02 | L6: 0.03 | M6: 0.03 | N6: 0.03 | O6: 0.03 | P6: 0.04 | Q6: 0.04 | R6: 0.04 | S6: 0.05 | T6: 0.06 | U6: 0.06 | V6: 0.07 | W6: 0.09 | X6: 0.1

Sheet CALCULATION
A1: Z | B1: Symbol | C1: Metal | D1: UNEP category | E1: Other category | F1: Raw_data_primary | G1: Raw_data_type | H1: Secondary_production | I1: Production_yield | J1: Primary_refinery_production | K1: Total_refinery_production | L1: Unit | M1: Year | N1: Source_primary | O1: Comment
A2: 13 | B2: Al | C2: Aluminium | D2: Non-ferrous metal | F2: =MCS!G6 -> 70000 | G2: Refinery | H2: =(F2*IEA_secondary_prod!G2)/(1-IEA_secondary_prod!G2) -> 41111.111 | J2: =F2 -> 70000 | K2: =H2+J2 -> 111111.11 | L2: kt | M2: 2023 | N2: MCS | O2: Secondary production is estimated using IEA data
A3: 33 | B3: As | C3: Arsenic | D3: Specialty metal | F3: =MCS!G14 -> 61500 | G3: Refinery | J3: =F3 -> 61500 | K3: =H3+J3 -> 61500 | L3: t | M3: 2023 | N3: MCS
A4: 5 | B4: B | C4: Boron | D4: Specialty metal | F4: =MCS!G29 -> 3938 | G4: Mine | I4: =ChartierPoncelet!D6 -> 0.776 | J4: =F4*I4 -> 3055.888 | K4: =H4+J4 -> 3055.888 | L4: kt | M4: 2023 | N4: MCS+ChartierPoncelet
A5: 48 | B5: Cd | C5: Cadmium | D5: Specialty metal | F5: =MCS!G34 -> 24100 | G5: Refinery | J5: =F5 -> 24100 | K5: =H5+J5 -> 24100 | L5: t | M5: 2023 | N5: MCS
A6: 24 | B6: Cr | C6: Chromium | D6: Ferrous metal | F6: =MYB!H3 -> 15700 | G6: Refinery | J6: =F6 -> 15700 | K6: =H6+J6 -> 15700 | L6: kt | M6: 2023 | N6: MYB
A7: 27 | B7: Co | C7: Cobalt | D7: Specialty metal | F7: =MYB!H4 -> 180000 | G7: Refinery | H7: =F7*IEA_secondary_prod!G3/(1-IEA_secondary_prod!G3) -> 20000 | J7: =F7 -> 180000 | K7: =H7+J7 -> 200000 | L7: t | M7: 2023 | N7: MYB | O7: Secondary production is estimated using IEA data
A8: 29 | B8: Cu | C8: Copper | D8: Non-ferrous metal | F8: =MCS!G56*(1-(MYB!H16/MYB!H12)) -> 22712.4 | G8: Refinery | H8: =MCS!G56*(MYB!H16/MYB!H12) -> 4287.6 | J8: =F8 -> 22712.4 | K8: =H8+J8 -> 27000 | L8: kt | M8: 2023 | N8: MCS+MYB | O8: Secondary production is estimated using IEA data
A9: 66 | B9: Dy | C9: Dysprosium | D9: Specialty metal | E9: REE | F9: =MCS!G160*Lundaev!C38 -> 2079.4293 | G9: Mine | I9: =ChartierPoncelet!D15 -> 0.66218119 | J9: =F9*I9 -> 1376.9589 | K9: =H9+J9 -> 1376.9589 | L9: t | M9: 2023 | N9: MCS+Lundaev+ChartierPoncelet
A10: - | B10: - | C10: Ferromanganese | D10: - | F10: =MYB!H17*(MCS!G118/MCS!G117) -> 5028686.9 | G10: Refinery | J10: =F10 -> 5028686.9 | K10: =H10+J10 -> 5028686.9 | L10: t | M10: 2023 | N10: MYB | O10: MYB displays data for 2022. 2023 production adjusted with MCS trend for manganese
A11: - | B11: - | C11: Ferronickel | D11: - | F11: =MYB!H30*(MCS!G131/MCS!G129) -> 2156593.4 | G11: Refinery | J11: =F11 -> 2156593.4 | K11: =H11+J11 -> 2156593.4 | L11: t | M11: 2023 | N11: MYB | O11: MYB displays data for 2021. 2023 production adjusted with MCS trend for nickel
A12: 31 | B12: Ga | C12: Gallium | D12: Specialty metal | F12: =MCS!G69 -> 633000 | G12: Refinery | J12: =F12 -> 633000 | K12: =H12+J12 -> 633000 | L12: kg | M12: 2023 | N12: MCS
A13: - | B13: - | C13: Graphite | D13: - | F13: =MCS!G80 -> 1530000 | G13: Refinery | J13: =F13 -> 1530000 | K13: =H13+J13 -> 1530000 | L13: t | M13: 2023 | N13: MCS+ChartierPoncelet | O13: No production yield is given by Chartier-Poncelet
A14: 72 | B14: Hf | C14: Hafnium | F14: x | G14: x | H14: x | I14: x | J14: x | K14: x | L14: x | M14: 2023 | O14: No data is available, probably merged with zirconium
A15: 49 | B15: In | C15: Indium | D15: Specialty metal | F15: =MCS!G86 -> 1020 | G15: Refinery | J15: =F15 -> 1020 | K15: =H15+J15 -> 1020 | L15: t | M15: 2023 | N15: MCS
A16: 77 | B16: Ir | C16: Iridium | D16: Precious metal | E16: PGMs | F16: =MYB!H21*(MCS!G149/MCS!G150) -> 3394.8276 | G16: Mine | I16: =ChartierPoncelet!D26 -> 0.5757696 | J16: =F16*I16 -> 1954.6385 | K16: =H16+J16 -> 1954.6385 | L16: kg | M16: 2023 | N16: MYB+MCS | O16: MYB displays data for 2022. 2023 production adjusted with MCS trend for PGMs
A17: 57 | B17: La | C17: Lanthanum | E17: REE | F17: =MCS!G160*Lundaev!C30 -> 99536.866 | G17: Mine | I17: =ChartierPoncelet!D27 -> 0.60009237 | J17: =F17*I17 -> 59731.313 | K17: =H17+J17 -> 59731.313 | L17: t | M17: 2023 | N17: MYB+Lundaev+ChartierPoncelet
A18: 82 | B18: Pb | C18: Lead | D18: Non-ferrous metal | F18: =MYB!H24*(MCS!G102/MCS!G103) -> 4164237.7 | G18: Refinery | H18: =MYB!H25*(MCS!G102/MCS!G103) -> 7280067.3 | J18: =F18 -> 4164237.7 | K18: =H18+J18 -> 11444305 | L18: kt | M18: 2023 | N18: MYB | O18: MYB displays data for 2022. 2023 production adjusted with MCS trend for lead
A19: 3 | B19: Li | C19: Lithium | D19: Specialty metal | F19: =MCS!G109 -> 204000 | G19: Mine | H19: =(F19*IEA_secondary_prod!G5)/(1-IEA_secondary_prod!G5) -> 6309.2784 | I19: =ChartierPoncelet!D28 -> 0.69917047 | J19: =F19*I19 -> 142630.78 | K19: =H19+J19 -> 148940.05 | L19: t | M19: 2023 | N19: MCS+ChartierPoncelet | O19: Secondary production is estimated using IEA data
A20: 12 | B20: Mg | C20: Magnesium | F20: =MCS!G113 -> 900 | G20: Refinery | J20: =F20 -> 900 | K20: =H20+J20 -> 900 | L20: kt | M20: 2023 | N20: MCS
A21: 25 | B21: Mn | C21: Manganese | D21: Ferrous metal | F21: =MCS!G118 -> 19600 | G21: Mine | I21: =ChartierPoncelet!D31 -> 0.7 | J21: =F21*I21 -> 13720 | K21: =H21+J21 -> 13720 | L21: kt | M21: 2023 | N21: MCS+ChartierPoncelet
A22: 42 | B22: Mo | C22: Molybdenum | D22: Ferrous metal | F22: =MCS!G125 -> 248000 | G22: Mine | I22: =ChartierPoncelet!D32 -> 0.6 | J22: =F22*I22 -> 148800 | K22: =H22+J22 -> 148800 | L22: t | M22: 2023 | N22: MCS+ChartierPoncelet
A23: 60 | B23: Nd | C23: Neodymium | D23: Specialty metal | E23: REE | F23: =MCS!G160*Lundaev!C33 -> 63181.47 | G23: Mine | I23: =ChartierPoncelet!D34 -> 0.59854391 | J23: =F23*I23 -> 37816.884 | K23: =H23+J23 -> 37816.884 | L23: t | M23: 2023 | N23: MCS+Lundaev+ChartierPoncelet
A24: 28 | B24: Ni | C24: Nickel | D24: Ferrous metal | F24: =MYB!H28*(MCS!G131/MCS!G129) -> 3516483.5 | G24: Refinery | H24: =(F24*IEA_secondary_prod!G6)/(1-IEA_secondary_prod!G6) -> 35520.036 | J24: =F24 -> 3516483.5 | K24: =H24+J24 -> 3552003.6 | L24: t | M24: 2023 | N24: MYB | O24: MYB displays data for 2021. 2023 production adjusted with MCS trend for nickel. Secondary production is estimated using IEA data
A25: 41 | B25: Nb | C25: Niobium | F25: =MCS!G134 -> 110000 | G25: Mine | I25: =ChartierPoncelet!D33 -> 0.71 | J25: =F25*I25 -> 78100 | K25: =H25+J25 -> 78100 | L25: t | M25: 2023 | N25: MCS+ChartierPoncelet
A26: - | B26: - | C26: PGMs | D26: Precious metal | E26: PGMs | F26: =(MCS!G149-MYB!H22) -> 171940 | G26: Mine | I26: =ChartierPoncelet!D40 -> 0.68191896 | J26: =F26*I26 -> 117249.15 | K26: =H26+J26 -> 117249.15 | L26: kg | M26: 2023 | N26: MCS+MYB+Chartier Poncelet | O26: All PGMs minus iridium. Using the production yield of platinum
A27: 59 | B27: Pr | C27: Praseodymium | D27: Specialty metal | E27: REE | F27: =MCS!G160*Lundaev!C32 -> 19355.859 | G27: Mine | I27: =ChartierPoncelet!D39 -> 0.59542492 | J27: =F27*I27 -> 11524.961 | K27: =H27+J27 -> 11524.961 | L27: t | M27: 2023 | N27: MCS+Lundaev+ChartierPoncelet
A28: 34 | B28: Se | C28: Selenium | D28: Specialty metal | F28: =MCS!G168 -> 3530 | G28: Refinery | J28: =F28 -> 3530 | K28: =H28+J28 -> 3530 | L28: t | M28: 2023 | N28: MCS
A29: 14 | B29: Si | C29: Silicon | D29: Non-ferrous metal | F29: =MCS!G173 -> 4280 | G29: Refinery | J29: =F29 -> 4280 | K29: =H29+J29 -> 4280 | L29: kt | M29: 2023 | N29: MCS
A30: 47 | B30: Ag | C30: Silver | D30: Precious metal | F30: =MCS!G176 -> 25476 | G30: Mine | I30: =ChartierPoncelet!D2 -> 0.8425656 | J30: =F30*I30 -> 21465.201 | K30: =H30+J30 -> 21465.201 | L30: t | M30: 2023 | N30: MCS+ChartierPoncelet+Silver Institute | O30: Secondary production is estimated using Silver Institute share of recycling data
A31: 73 | B31: Ta | C31: Tantalum | F31: =MCS!G191 -> 2040 | G31: Mine | I31: =ChartierPoncelet!D51 -> 0.64768683 | J31: =F31*I31 -> 1321.2811 | K31: =H31+J31 -> 1321.2811 | L31: t | M31: 2023 | N31: MCS+ChartierPoncelet
A32: 52 | B32: Te | C32: Tellurium | D32: Specialty metal | F32: =MCS!G192 -> 944 | G32: Refinery | J32: =F32 -> 944 | K32: =H32+J32 -> 944 | L32: t | M32: 2023 | N32: MCS
A33: 65 | B33: Tb | C33: Terbium | D33: Specialty metal | E33: REE | F33: =MCS!G160*Lundaev!C37 -> 581.87097 | G33: Mine | I33: =ChartierPoncelet!D52 -> 0.64609876 | J33: =F33*I33 -> 375.94611 | K33: =H33+J33 -> 375.94611 | L33: t | M33: 2023 | N33: MCS+Lundaev+ChartierPoncelet
A34: 50 | B34: Sn | C34: Tin | D34: Non-ferrous metal | F34: =MCS!G195 -> 305000 | G34: Mine | I34: =ChartierPoncelet!D49 -> 0.88235294 | J34: =F34*I34 -> 269117.65 | K34: =H34+J34 -> 269117.65 | L34: t | M34: 2023 | N34: MCS+ChartierPoncelet
A35: 22 | B35: Ti | C35: Titanium | F35: =MCS!G200 -> 320000 | G35: Refinery | J35: =F35 -> 320000 | K35: =F35 -> 320000 | L35: t | M35: 2023 | N35: MCS
A36: 74 | B36: W | C36: Tungsten | F36: =MCS!G219 -> 79500 | G36: Mine | I36: =ChartierPoncelet!D58 -> 0.88571429 | J36: =F36*I36 -> 70414.286 | K36: =H36+J36 -> 70414.286 | L36: t | M36: 2023 | N36: MCS
A37: 23 | B37: V | C37: Vanadium | D37: Ferrous metal | F37: =MCS!G220 -> 104000 | G37: Mine | I37: =ChartierPoncelet!D57 -> 0.32871263 | J37: =F37*I37 -> 34186.113 | K37: =H37+J37 -> 34186.113 | L37: t | M37: 2023 | N37: MCS+ChartierPoncelet
A38: 39 | B38: Y | C38: Yttrium | E38: REE | F38: =MCS!G160*Lundaev!C44 -> 11910.345 | G38: Mine | I38: =ChartierPoncelet!D59 -> 0.66407609 | J38: =F38*I38 -> 7909.3755 | K38: =H38+J38 -> 7909.3755 | L38: t | M38: 2023 | N38: MCS+ChartierPoncelet
A39: 30 | B39: Zn | C39: Zinc | D39: Non-ferrous metal | F39: =MYB!H48*(MCS!G230/MCS!G231) -> 12487.2 | G39: Refinery | H39: =MYB!H50*(MCS!G230/MCS!G231) -> 1016.4 | J39: =F39 -> 12487.2 | K39: =H39+J39 -> 13503.6 | L39: kt | M39: 2023 | N39: MYB | O39: MYB displays data for 2022. 2023 production adjusted with MCS trend for zinc
A40: 40 | B40: Zr | C40: Zirconium | D40: Specialty metal | F40: =MCS!G233 -> 1440 | G40: Mine | I40: =ChartierPoncelet!D62 -> 0.855 | J40: =F40*I40 -> 1231.2 | K40: =H40+J40 -> 1231.2 | L40: kt | M40: 2023 | N40: MCS+ChartierPoncelet

Sheet data_availability
A1: Z | B1: Symbol | C1: Mineral | D1: UNEP category | E1: Other category | F1: In Chartier-Poncelet et al (2022) | G1: In MCS | H1: Mine_production_in_MCS | I1: Refinery_production_in_MCS | J1: MCS_details | K1: In MYB | L1: MYB_latest_year | M1: MYB_details | N1: MYB_details_2
A2: 13 | B2: Al | C2: Aluminium | D2: Non-ferrous metal | F2: YES | G2: YES | H2: YES | I2: YES | J2: Smelter production | K2: YES | L2: 2021 | M2: Primary production
A3: 33 | B3: As | C3: Arsenic | D3: Specialty metal | F3: YES | G3: YES | H3: NO | I3: YES | J3: Plant production, arsenic trioxide or calculated equivalent. | K3: YES | L3: 2023 | M3: Arsenic trioxide production
A4: 5 | B4: B | C4: Boron | D4: Specialty metal | F4: YES | G4: YES | H4: YES | I4: NO | J4: All types. We assume it is mine production. | K4: YES | L4: 2023 | M4: Boron minerals production
A5: 48 | B5: Cd | C5: Cadmium | D5: Specialty metal | F5: YES | G5: YES | H5: NO | I5: YES | J5: Refinery production | K5: YES | L5: 2022 | M5: Refinery production
A6: 24 | B6: Cr | C6: Chromium | D6: Ferrous metal | F6: YES | G6: YES | H6: YES | I6: NO | J6: Mine production, gross weight, marketable chromite ore | K6: YES | L6: 2023 | M6: Chromite ore, ferrochromium, chromium metal, cromium chemicals and stainles steel
A7: 27 | B7: Co | C7: Cobalt | D7: Specialty metal | F7: YES | G7: YES | H7: YES | I7: NO | J7: Mine production, metric tons of contained cobalt | K7: YES | L7: 2023 | M7: Mine and refinery production
A8: 29 | B8: Cu | C8: Copper | D8: Non-ferrous metal | F8: YES | G8: YES | H8: YES | I8: YES | J8: Mine (recoverable copper content) and refinery production | K8: YES | L8: 2020 | M8: Mine production, smelter, refinery | N8: Secondary production is included
A9: 66 | B9: Dy | C9: Dysprosium | D9: Specialty metal | E9: REE | F9: YES | G9: AGG | H9: AGG | I9: NO | J9: - | K9: AGG | L9: 2020 | M9: Aggregated in REEs (mine production)
A10: - | B10: - | C10: Ferromanganese | D10: - | F10: NO | G10: NO | H10: NO | I10: NO | J10: - | K10: YES | L10: 2022 | M10: Production (no type specified) | N10: Part of the manganese file
A11: - | B11: - | C11: Ferronickel | D11: - | F11: NO | G11: NO | H11: NO | I11: NO | J11: - | K11: YES | M11: Primary production | N11: Part of the nickel file
A12: 31 | B12: Ga | C12: Gallium | D12: Specialty metal | F12: YES | G12: YES | H12: NO | I12: YES | J12: Primary production. We assume it is refinery production since it is a by-product. | K12: YES | M12: Primary production capacity, primary world production | N12: Look like the same value as MCS
A13: - | B13: - | C13: Graphite | D13: - | F13: NO | G13: YES | H13: YES | I13: NO | J13: Mine production | K13: YES | L13: 2022 | M13: Natural graphite production
A14: 72 | B14: Hf | C14: Hafnium | F14: YES | G14: NO | H14: NO | I14: NO | K14: NO
A15: 49 | B15: In | C15: Indium | D15: Specialty metal | F15: YES | G15: YES | H15: NO | I15: YES | J15: Refinery production | K15: YES | M15: Refinery production
A16: 77 | B16: Ir | C16: Iridium | D16: Precious metal | E16: PGM | F16: YES | G16: AGG | H16: AGG | I16: NO | J16: - | K16: AGG | M16: Aggregated in PGMs (refinery production) | N16: Not sure if it is included, we have palladium and platinum for sure
A17: 57 | B17: La | C17: Lanthanum | E17: REE | F17: YES | G17: AGG | H17: AGG | I17: NO | K17: AGG
A18: 82 | B18: Pb | C18: Lead | D18: Non-ferrous metal | F18: YES | G18: YES | H18: YES | I18: NO | J18: Mine production | K18: YES | M18: Mine and refinery production | N18: Secondary production is included
A19: 3 | B19: Li | C19: Lithium | D19: Specialty metal | F19: YES | G19: YES | H19: YES | I19: NO | J19: Mine production | K19: YES | M19: Gross weight, lithium content and lithium-carbonate equivalent | N19: Difference between different types per country (carbonate, chloride, spodumene, concentrate…)
A20: 12 | B20: Mg | C20: Magnesium | F20: YES | G20: YES | H20: YES | I20: YES
A21: 25 | B21: Mn | C21: Manganese | D21: Ferrous metal | F21: YES | G21: YES | H21: YES | I21: NO | J21: Mine production | K21: YES | M21: Manganese ore, ferromanganese and silicomanganese production
A22: 42 | B22: Mo | C22: Molybdenum | D22: Ferrous metal | F22: YES | G22: YES | H22: YES | I22: NO | J22: Mine production | K22: YES | M22: Mine production
A23: 60 | B23: Nd | C23: Neodymium | D23: Specialty metal | E23: REE | F23: YES | G23: AGG | H23: AGG | I23: NO | J23: - | K23: AGG | L23: 2020 | M23: Aggregated in REEs (mine production)
A24: 28 | B24: Ni | C24: Nickel | D24: Ferrous metal | F24: YES | G24: YES | H24: YES | I24: NO | J24: Mine production | K24: YES | L24: 2021 | M24: Mine production and primary production | N24: For primary production difference between chemicals, ferronickel, metal, oxide sinter and unspecified
A25: 41 | B25: Nb | C25: Niobium | F25: YES | G25: YES | H25: YES | I25: NO | K25: YES
A26: - | C26: PGMs (other than iridum) | D26: Precious metal | E26: PGM | F26: YES | G26: AGG | H26: YES | I26: NO | J26: Mine production | K26: YES | M26: Refinery production
A27: 59 | B27: Pr | C27: Praseodymium | D27: Specialty metal | E27: REE | F27: YES | G27: AGG | H27: AGG | I27: NO | J27: - | K27: AGG | L27: 2020 | M27: Aggregated in REEs (mine production)
A28: 34 | B28: Se | C28: Selenium | D28: Specialty metal | F28: YES | G28: YES | H28: NO | I28: YES | J28: Refinery production | K28: YES | M28: Refinery production
A29: 14 | B29: Si | C29: Silicon | D29: Non-ferrous metal | F29: YES | G29: YES | H29: NO | I29: YES | J29: Plant production, silicon metal | K29: YES | L29: 2022 | M29: Ferrosilicon and silicon metal production
A30: 47 | B30: Ag | C30: Silver | D30: Precious metal | F30: YES | G30: YES | H30: YES | I30: NO | J30: Mine production | K30: YES | M30: Mine production
A31: 73 | B31: Ta | C31: Tantalum | F31: YES | G31: YES | H31: YES | I31: NO
A32: 52 | B32: Te | C32: Tellurium | D32: Specialty metal | F32: YES | G32: YES | H32: NO | I32: YES | J32: Refinery production | K32: YES | M32: Refinery production | N32: Part of the selenium file
A33: 65 | B33: Tb | C33: Terbium | D33: Specialty metal | E33: REE | F33: YES | G33: AGG | H33: AGG | I33: NO | J33: - | K33: AGG | L33: 2020 | M33: Aggregated in REEs (mine production)
A34: 50 | B34: Sn | C34: Tin | D34: Non-ferrous metal | F34: YES | G34: YES | H34: YES | I34: NO | J34: Mine production | K34: YES | M34: Mine and smelter production | N34: Secondary production is included
A35: 22 | B35: Ti | C35: Titanium | F35: YES | G35: YES | H35: YES | I35: YES
A36: 74 | B36: W | C36: Tungsten | F36: YES | G36: YES | H36: YES | I36: NO
A37: 23 | B37: V | C37: Vanadium | D37: Ferrous metal | F37: YES | G37: YES | H37: YES | I37: NO | J37: Mine production | K37: YES | M37: Production from coproduct steel slag and primary ores only
A38: 39 | B38: Y | C38: Yttrium | E38: REE | F38: YES | G38: AGG | H38: AGG | I38: NO
A39: 30 | B39: Zn | C39: Zinc | D39: Non-ferrous metal | F39: YES | G39: YES | H39: YES | I39: NO | J39: Mine production ( zinc content of concentrates and direct shipping ores) | K39: YES | M39: Mine and smelter production | N39: Secondary production is included
A40: 40 | B40: Zr | C40: Zirconium | D40: Specialty metal | F40: YES | G40: YES | H40: YES | I40: NO | J40: Mine production (Zirconium ores and zircon concentrates) | K40: YES | M40: Mine production

Sheet IEA_secondary_prod
A1: Global Critical Minerals Outloook 2024: Share of secondary production in % in the NZE | B1: 2018 | C1: 2019 | D1: 2020 | E1: 2021 | F1: 2022 | G1: 2023 | H1: 2024 | I1: 2025 | J1: 2026 | K1: 2027 | L1: 2028 | M1: 2029 | N1: 2030 | O1: 2031 | P1: 2032 | Q1: 2033 | R1: 2034 | S1: 2035 | T1: 2036 | U1: 2037 | V1: 2038 | W1: 2039 | X1: 2040
A2: Aluminium | B2: 0.35 | C2: 0.35 | D2: 0.35 | E2: 0.36 | F2: 0.36 | G2: 0.37 | H2: 0.38 | I2: 0.39 | J2: 0.39 | K2: 0.4 | L2: 0.41 | M2: 0.41 | N2: 0.42 | O2: 0.42 | P2: 0.43 | Q2: 0.43 | R2: 0.44 | S2: 0.44 | T2: 0.45 | U2: 0.46 | V2: 0.46 | W2: 0.47 | X2: 0.47
A3: Cobalt | B3: 0.06 | C3: 0.07 | D3: 0.07 | E3: 0.08 | F3: 0.09 | G3: 0.1 | H3: 0.11 | I3: 0.11 | J3: 0.11 | K3: 0.12 | L3: 0.12 | M3: 0.12 | N3: 0.12 | O3: 0.13 | P3: 0.14 | Q3: 0.15 | R3: 0.16 | S3: 0.18 | T3: 0.19 | U3: 0.21 | V3: 0.24 | W3: 0.26 | X3: 0.29
A4: Copper | B4: 0.17 | C4: 0.17 | D4: 0.17 | E4: 0.17 | F4: 0.17 | G4: 0.17 | H4: 0.17 | I4: 0.17 | J4: 0.17 | K4: 0.17 | L4: 0.17 | M4: 0.17 | N4: 0.18 | O4: 0.18 | P4: 0.19 | Q4: 0.2 | R4: 0.21 | S4: 0.22 | T4: 0.23 | U4: 0.24 | V4: 0.26 | W4: 0.27 | X4: 0.28
A5: Lithium | B5: 0.01 | C5: 0.01 | D5: 0.01 | E5: 0.01 | F5: 0.02 | G5: 0.03 | H5: 0.06 | I5: 0.06 | J5: 0.06 | K5: 0.06 | L5: 0.05 | M5: 0.05 | N5: 0.05 | O5: 0.05 | P5: 0.05 | Q5: 0.06 | R5: 0.06 | S5: 0.07 | T5: 0.07 | U5: 0.08 | V5: 0.09 | W5: 0.1 | X5: 0.12
A6: Nickel | B6: 0 | C6: 0 | D6: 0 | E6: 0 | F6: 0.01 | G6: 0.01 | H6: 0.02 | I6: 0.02 | J6: 0.02 | K6: 0.02 | L6: 0.03 | M6: 0.03 | N6: 0.03 | O6: 0.03 | P6: 0.04 | Q6: 0.04 | R6: 0.04 | S6: 0.05 | T6: 0.06 | U6: 0.06 | V6: 0.07 | W6: 0.09 | X6: 0.1
A9: Recycling of critical minerals: share of total demand supplied by secondary production | B9: Scenario | C9: 2023 | D9: 2035 | E9: 2050
A10: Graphite | B10: STEPS | C10: 0.03 | D10: 0.01 | E10: 0.03
A11: Graphite | B11: APS | C11: 0.03 | D11: 0.01 | E11: 0.05
A12: Graphite | B12: NZS | C12: 0.03 | D12: 0.02 | E12: 0.15
A13: Copper | B13: STEPS | C13: 0.08 | D13: 0.21 | E13: 0.32
A14: Copper | B14: APS | C14: 0.08 | D14: 0.22 | E14: 0.39
A15: Copper | B15: NZS | C15: 0.08 | D15: 0.21 | E15: 0.39
A16: Lithium | B16: STEPS | C16: 0.03 | D16: 0.05 | E16: 0.22
A17: Lithium | B17: APS | C17: 0.03 | D17: 0.05 | E17: 0.22
A18: Lithium | B18: NZS | C18: 0.03 | D18: 0.07 | E18: 0.33
A19: Cobalt | B19: STEPS | C19: 0.11 | D19: 0.15 | E19: 0.32
A20: Cobalt | B20: APS | C20: 0.11 | D20: 0.17 | E20: 0.38
... A24: REE | B24: NZS | C24: 0.27 | D24: 0.28 | E24: 0.4
A27: Metals | B27: Title | C27: Source | D27: URL | E27: Comment
A28: Aluminium, copper, nickel, cobalt, lithium | B28: Historical recycled input rate for selected materials, 2015-2023 | C28: Recycling of critical minerals | D28: https://www.iea.org/data-and-statistics/charts/historical-recycled-input-rate-for-selected-materials-2015-2023 | E28: Only PNG images, CSV not available
A29: Copper | B29: Secondary supply volumes and share of total demand for copper in the Announced Pledges Scenario and Net Zero Emissions by 2050 Scenario, 2023-2050 | C29: Recycling of critical minerals | D29: https://www.iea.org/data-and-statistics/charts/secondary-supply-volumes-and-share-of-total-demand-for-copper-in-the-announced-pledges-scenario-and-net-zero-emissions-by-2050-scenario-2023-2050 | E29: Only PNG images, CSV not available
A30: Lithium | B30: Secondary supply volumes and share of total demand for lithium in the Announced Pledges Scenario and Net Zero Emissions by 2050 Scenario, 2023-2050 | C30: Recycling of critical minerals | D30: https://www.iea.org/data-and-statistics/charts/secondary-supply-volumes-and-share-of-total-demand-for-lithium-in-the-announced-pledges-scenario-and-net-zero-emissions-by-2050-scenario-2023-2050 | E30: Only PNG images, CSV not available
A31: Graphite | B31: Secondary supply volumes and share of total demand for graphite in the Announced Pledges Scenario and Net Zero Emissions by 2050 Scenario, 2023-2050 | C31: Recycling of critical minerals | D31: https://www.iea.org/data-and-statistics/charts/secondary-supply-volumes-and-share-of-total-demand-for-graphite-in-the-announced-pledges-scenario-and-net-zero-emissions-by-2050-scenario-2023-2050 | E31: Only PNG images, CSV not available
A32: Cobalt | B32: Secondary supply volumes and share of total demand for cobalt in the Announced Pledges Scenario and Net Zero Emissions by 2050 Scenario, 2023-2050 | C32: Recycling of critical minerals | D32: https://www.iea.org/data-and-statistics/charts/secondary-supply-volumes-and-share-of-total-demand-for-cobalt-in-the-announced-pledges-scenario-and-net-zero-emissions-by-2050-scenario-2023-2050 | E32: Only PNG images, CSV not available
A33: REE | B33: Secondary supply volumes and share of total demand for rare earths in the Announced Pledges Scenario and Net Zero Emissions by 2050 Scenario, 2023-2050 | C33: Recycling of critical minerals | D33: https://www.iea.org/data-and-statistics/charts/secondary-supply-volumes-and-share-of-total-demand-for-rare-earths-in-the-announced-pledges-scenario-and-net-zero-emissions-by-2050-scenario-2023-2050 | E33: Only PNG images, CSV not available
A34: Aluminium, copper, nickel, cobalt, lithium | B34: Share of secondary supply in total demand for selected materials in the Net Zero Scenario, 2010-2040 | C34: Global Critical Minerals Outloook 2024 | D34: https://www.iea.org/data-and-statistics/charts/share-of-secondary-supply-in-total-demand-for-selected-materials-in-the-net-zero-scenario-2010-2040 | E34: CSV available

Sheet CP_enduse
A1: Par_InitialDemand | B1: 03_Li | C1: 04_Be | D1: 05_B | E1: 12_Mg | F1: 13_Al | G1: 14_Si | H1: 21_Sc | I1: 22_Ti | J1: 23_V | K1: 24_Cr | L1: 25_Mn | M1: 26_Fe | N1: 27_Co | O1: 28_Ni | P1: 29_Cu | Q1: 30_Zn | R1: 31_Ga | S1: 32_Ge | T1: 33_As | U1: 34_Se | V1: 38_Sr | W1: 39_Y | X1: 40_Zr | Y1: 41_Nb | Z1: 42_Mo | AA1: 44_Ru | AB1: 45_Rh | AC1: 46_Pd | AD1: 47_Ag | AE1: 48_Cd | AF1: 49_In | AG1: 50_Sn | AH1: 51_Sb | AI1: 52_Te | AJ1: 56_Ba | AK1: 57_La | AL1: 58_Ce | AM1: 59_Pr | AN1: 60_Nd | AO1: 62_Sm | AP1: 63_Eu | AQ1: 64_Gd | AR1: 65_Tb | AS1: 66_Dy | AT1: 67_Ho | AU1: 68_Er | AV1: 69_Tm | AW1: 70_Yb | AX1: 71_Lu | AY1: 72_Hf | AZ1: 73_Ta | BA1: 74_W | BB1: 75_Re | BC1: 76_Os | BD1: 77_Ir | BE1: 78_Pt | BF1: 79_Au | BG1: 80_Hg | BH1: 81_Tl | BI1: 82_Pb | BJ1: 83_Bi
A2: Agricultural & environmental applications | D2: 0.06 | E2: 0.15279553 | Q2: 0.0071152956 | T2: 0.019946453 | U2: 0.1 | Z2: 0.039 | BG2: 0.037531807 | BJ2: 0.05
A3: Alloys & solders | D3: 0.04 | G3: 0.41 | K3: 0.0384 | L3: 0.04 | N3: 0.1973 | R3: 0.05 | T3: 0.023450966 | U3: 0.3 | X3: 0.01 | Y3: 0.03 | AA3: 0.16438356 | AD3: 0.057177783 | AF3: 0.13427332 | AH3: 0.095 | AI3: 0.15 | AK3: 0.097967609 | AL3: 0.18649094 | AM3: 0.037889436 | AN3: 0.023728218 | AQ3: 0.28431373 | AZ3: 0.18 | BA3: 0.23 | BB3: 0.8 | BC3: 0.1 | BI3: 0.02 | BJ3: 0.2805
A4: Aviation | C4: 0.1 | H4: 0.05 | I4: 0.017788462 | J4: 0.04 | O4: 0.032223416 | V4: 0.028333333 | AY4: 0.45
A5: Batteries (consumer electronics & lead acid) | B5: 0.21 | L5: 0.02 | N5: 0.3975 | O5: 0.05 | AE5: 0.64 | AF5: 0.05 | AH5: 0.259 | AK5: 0.094443082 | AL5: 0.010196253 | AM5: 0.014098596 | AN5: 0.0053224595 | BG5: 0.048982188 | BI5: 0.86
A6: Batteries (electric vehicle) | B6: 0.44 | N6: 0.106 | T6: 0.29329272 | AG6: 0.06 | AK6: 0.1654807 | AL6: 0.017810337 | AM6: 0.025064171 | AN6: 0.0094621502
A7: Batteries (utility & industrial) | J7: 0.025 | N7: 0.0265 | AE7: 0.16
A8: Biomedical & dental | AC8: 0.0273285 | AF8: 0.0028633406 | BD8: 0.09 | BE8: 0.026213703 | BF8: 0.0032673593 | BG8: 0.058100085
A9: Catalysts (heterogenous & stable env.) | J9: 0.02 | N9: 0.0186 | AA9: 0.49589041 | BB9: 0.075 | BC9: 0.45 | BD9: 0.26 | BE9: 0.022258118
A10: Catalysts (homogenous & aggressive env.) | B10: 0.025 | N10: 0.0372 | R10: 0.01 | Y10: 0.01 | Z10: 0.052 | AB10: 0.056179775 | AC10: 0.047127719 | AD10: 0.0053234488 | AH10: 0.058628571 | AX10: 0.18333333 | AY10: 0.07 | BA10: 0.02 | BB10: 0.075 | BD10: 0.39 | BE10: 0.098571665 | BG10: 0.25996607 | BJ10: 0.05
A11: Chemicals | E11: 0.061944134 | L11: 0.05 | O11: 0.01 | P11: 0.005 | U11: 0.05 | X11: 0.0522 | AD11: 0.01 | AG11: 0.055384615 | AK11: 0.44299778 | AL11: 0.045030203 | BG11: 0.058736217
A12: Construction | D12: 0.49 | E12: 0.16842905 | F12: 0.33432822 | J12: 0.30333333 | K12: 0.11562 | L12: 0.315 | M12: 0.31234899 | O12: 0.16326531 | P12: 0.28 | Q12: 0.33106961 | Y12: 0.4 | Z12: 0.409 | AG12: 0.03 | AH12: 0.06288 | BI12: 0.04
A13: Cutting tools | N13: 0.0746 | Y13: 0.02 | Z13: 0.0238 | AY13: 0.15 | AZ13: 0.05 | BA13: 0.55
A14: Electronics | C14: 0.15 | G14: 0.0175 | M14: 0.03 | O14: 0.052040816 | P14: 0.11180328 | Q14: 0.095307918 | R14: 0.6 | S14: 0.38823529 | T14: 0.039242606 | U14: 0.04 | W14: 0.10133136 | Y14: 0.02 | Z14: 0.005 | AA14: 0.33972603 | AB14: 0.0056179775 | AC14: 0.063301729 | AD14: 0.24497723 | AF14: 0.59286334 | AG14: 0.3995 | AH14: 0.3668 | AI14: 0.3 | AK14: 0.0035578722 | AL14: 0.0091408875 | AM14: 0.53557008 | AN14: 0.65117703 | AP14: 0.16734197 | AQ14: 0.037862643 | AR14: 0.17889099 | AS14: 0.68103271 | AU14: 0.25 | AY14: 0.06 | AZ14: 0.48 | BA14: 0.07 | BE14: 0.028490391 | BF14: 0.061656716 | BG14: 0.031170483 | BH14: 0.9
A15: Glass & ceramics | B15: 0.175 | D15: 0.18 | J15: 0.005 | N15: 0.052 | T15: 0.2838331 | U15: 0.2 | V15: 0.085 | W15: 0.20915033 | X15: 0.5556 | Z15: 0.00975 | AE15: 0.048 | AF15: 0.015 | AH15: 0.021 | AK15: 0.062400762 | AL15: 0.12883031 | AM15: 0.070921252 | AN15: 0.057096025 | AT15: 0.33333333 | AU15: 0.72222222 | AX15: 0.18333333
A16: Glass manufacturing | AB16: 0.047752809 | AG16: 0.02 | BE16: 0.052020401
A17: Household appliances | B17: 0.025 | F17: 0.039177433 | K17: 0.0504576 | L17: 0.028 | M17: 0.037514124 | O17: 0.22
A18: Infrastructure | F18: 0.16598259 | K18: 0.1429632 | M18: 0.20765101 | P18: 0.16 | T18: 0.26606727 | Y18: 0.16 | AY18: 0.16 | BI18: 0.01
A19: Jewellery & investment | AC19: 0.011433352 | AD19: 0.42960232 | BD19: 0.04 | BE19: 0.32894954 | BF19: 0.92336985
A20: Lighting | R20: 0.1 | S20: 0.09 | W20: 0.68559674 | Z20: 0.005 | AF20: 0.02 | AK20: 0.010891159 | AL20: 0.027981573 | AM20: 0.093035286 | AN20: 0.007682188 | AP20: 0.79736391 | AQ20: 0.18762755 | AR20: 0.53283315 | BA20: 0.02 | BG20: 0.030110263
A21: Magnets (large) | Y21: 0.01 | AM21: 0.057773754 | AN21: 0.071018405 | AQ21: 0.35294118 | AR21: 0.072413793 | AS21: 0.085741529 | AT21: 0.33333333
A22: Magnets (small) | R22: 0.04 | V22: 0.22666667
A23: Mechanical equipment | C23: 0.15 | F23: 0.089224811 | J23: 0.30333333 | K23: 0.3111552 | L23: 0.091 | M23: 0.16 | O23: 0.31 | P23: 0.12 | Q23: 0.07 | Z23: 0.3071
A24: Metallurgy & metalworking (process) | B24: 0.025 | E24: 0.0067597765 | F24: 0.03 | K24: 0.017 | L24: 0.261 | T24: 0.050715924 | U24: 0.1 | V24: 0.056666667 | X24: 0.15
A25: Other electrical & metal products | B25: 0.05 | H25: 0.05 | L25: 0.07 | M25: 0.077966102 | Q25: 0.095307918
A26: Other industrial, military & energy applications | C26: 0.22 | D26: 0.095 | E26: 0.043311732 | F26: 0.020403555 | G26: 0.13083333 | I26: 0.077811538 | K26: 0.141924 | N26: 0.0276 | O26: 0.041632653 | P26: 0.14237705 | R26: 0.05 | S26: 0.26 | U26: 0.05 | V26: 0.028333333 | W26: 0.0039215686 | X26: 0.02 | Y26: 0.11 | AB26: 0.016853933 | AC26: 0.015337423 | AD26: 0.13481752 | AE26: 0.008 | AF26: 0.075 | AG26: 0.1505 | AH26: 0.04044 | AJ26: 0.1 | AK26: 0.093045411 | AL26: 0.08380011 | AM26: 0.021373528 | AN26: 0.0037075341 | AO26: 0.97087379 | AP26: 0.035294118 | AQ26: 0.037254902 | AR26: 0.051724138 | AS26: 0.017647059 | AT26: 0.33333333 | AU26: 0.027777778 | AV26: 0.55 | AW26: 0.55 | AX26: 0.18333333 | AY26: 0.11 | AZ26: 0.29 | BB26: 0.05 | BD26: 0.16 | BE26: 0.037393638 | BF26: 0.011706079 | BG26: 0.069974555 | BI26: 0.017 | BJ26: 0.1
A27: Other miscellaneous | B27: 0.05 | D27: 0.095 | G27: 0.13083333 | I27: 0.019 | N27: 0.0627 | Q27: 0.03 | U27: 0.05 | X27: 0.0722 | AF27: 0.03 | AI27: 0.05 | AJ27: 0.1 | AO27: 0.029126214 | BA27: 0.11 | BD27: 0.06 | BE27: 0.037393638 | BG27: 0.037531807 | BH27: 0.1 | BJ27: 0.1
A28: Other punctual applications | D28: 0.04 | G28: 0.13083333 | T28: 0.023450966 | U28: 0.05 | V28: 0.22666667 | AH28: 0.02 | AI28: 0.05 | AK28: 0.014925373 | AL28: 0.35969248 | AM28: 0.020402004 | AN28: 0.0027188583 | AQ28: 0.1 | AV28: 0.45 | AW28: 0.45 | AX28: 0.45 | BC28: 0.45 | BG28: 0.36789652 | BI28: 0.023 | BJ28: 0.0695
A29: Packaging | E29: 0.011675978 | F29: 0.20162363 | L29: 0.02 | M29: 0.004519774 | S29: 0.2 | AG29: 0.11470588
A30: Paint | I30: 0.532 | Z30: 0.00975 | BI30: 0.03
A31: Paper | I31: 0.114
A32: Pharmaceutics & cosmetics | I32: 0.0114 | BE32: 0.0029126337 | BJ32: 0.1
A33: Photography | AD33: 0.038742877
A34: Plastics | I34: 0.228 | Z34: 0.0195 | AE34: 0.06 | AG34: 0.12461538 | AH34: 0.013371429
A35: Protective coatings | Q35: 0.12038895 | AE35: 0.084 | AG35: 0.015294118
A36: Refractories | E36: 0.52558659 | K36: 0.002 | X36: 0.14
A37: Rubber | Q37: 0.05 | AI37: 0.05
A38: Solar cells | G38: 0.18 | R38: 0.05 | S38: 0.061764706 | U38: 0.06 | AD38: 0.07935882 | AF38: 0.08 | AI38: 0.4
A39: Solid oxide fuel cells | H39: 0.9
A40: Telecommunication | C40: 0.12 | P40: 0.050819672 | R40: 0.1
...

Sheet MCS
A1: COMMODITY | B1: COUNTRY | C1: TYPE | D1: DATA_TYPE | E1: UNIT_MEAS | F1: YEAR | G1: VALUE | H1: NOTES
A2: Abrasives | B2: World total | C2: Plant capacity, fused aluminum oxide | D2: Capacity | E2: metric tons | F2: 2023 | G2: 1310000
A3: Abrasives | B3: World total | C3: Plant capacity, silicon carbide | D3: Capacity | E3: metric tons | F3: 2023 | G3: 1010000
A4: Abrasives | B4: World total | C4: Plant capacity, fused aluminum oxide | D4: Capacity | E4: metric tons | F4: 2024 | G4: 1310000
A5: Abrasives | B5: World total | C5: Plant capacity, silicon carbide | D5: Capacity | E5: metric tons | F5: 2024 | G5: 1010000
A6: Aluminum | B6: World total | C6: Smelter production, aluminum | D6: Production | E6: thousand metric tons | F6: 2023 | G6: 70000
A7: Aluminum | B7: World total | C7: Smelter production, aluminum | D7: Capacity | E7: thousand metric tons | F7: 2023 | G7: 78300
A8: Aluminum | B8: World total | C8: Smelter production, aluminum | D8: Capacity | E8: thousand metric tons | F8: 2024 | G8: 78400
A9: Aluminum | B9: World total | C9: Smelter production, aluminum | D9: Production | E9: thousand metric tons | F9: 2024 | G9: 72000
A10: Antimony | B10: World total | C10: Mine production, antimony content | D10: Reserves | E10: metric tons | F10: 2024 | G10: >2000000
A11: Antimony | B11: World total | C11: Mine production, antimony content | D11: Production | E11: metric tons | F11: 2023 | G11: 106000
A12: Antimony | B12: World total | C12: Mine production, antimony content | D12: Production | E12: metric tons | F12: 2024 | G12: 100000
A13: Arsenic | B13: World total | C13: Plant production, arsenic trioxide or calculated equivalent. | D13: Production | E13: metric tons | F13: 2024 | G13: 58000
A14: Arsenic | B14: World total | C14: Plant production, arsenic trioxide or calculated equivalent. | D14: Production | E14: metric tons | F14: 2023 | G14: 61500
A15: Arsenic | B15: World total | C15: Plant production, arsenic trioxide or calculated equivalent. | D15: Capacity | E15: metric tons | F15: 2024 | G15: 81000
A16: Asbestos | B16: World total | C16: Mine production, asbestos | D16: Production | E16: metric tons | F16: 2024 | G16: 1200000
A17: Asbestos | B17: World total | C17: Mine production, asbestos | D17: Production | E17: metric tons | F17: 2023 | G17: 1240000
A18: Barite | B18: World total | C18: Mine production, barite, estimated | D18: Production | E18: thousand metric tons | F18: 2024 | G18: 8200 | H18: excludes U.S. production
A19: Barite | B19: World total | C19: Mine production, barite, estimated | D19: Production | E19: thousand metric tons | F19: 2023 | G19: 8080 | H19: excludes U.S. production
A20: Bauxite | B20: World total | C20: Refinery production, alumina - calcined equivalent weights | D20: Production | E20: thousand metric dry tons | F20: 2024 | G20: 142000
A21: Bauxite | B21: World total | C21: Mine production, bauxite, dry tons | D21: Production | E21: thousand metric dry tons | F21: 2024 | G21: 450000 | H21: Excludes U.S. production.
A22: Bauxite | B22: World total | C22: Mine production, bauxite, dry tons | D22: Production | E22: thousand metric dry tons | F22: 2023 | G22: 438000 | H22: Excludes U.S. production.
A23: Bauxite | B23: World total | C23: Mine production, bauxite, dry tons | D23: Reserves | E23: thousand metric dry tons | F23: 2024 | G23: 29000000
A24: Bauxite | B24: World total | C24: Refinery production, alumina - calcined equivalent weights | D24: Production | E24: thousand metric dry tons | F24: 2023 | G24: 141000
A25: Beryllium | B25: World total | C25: Mine production, beryllium content | D25: Production | E25: metric tons | F25: 2024 | G25: 360
A26: Beryllium | B26: World total | C26: Mine production, beryllium content | D26: Production | E26: metric tons | F26: 2023 | G26: 325
A27: Bismuth | B27: World total | C27: Refinery production | D27: Production | E27: metric tons | F27: 2023 | G27: 16200
A28: Bismuth | B28: World total | C28: Refinery production | D28: Production | E28: metric tons | F28: 2024 | G28: 16000
A29: Boron | B29: World total | C29: Boron all types | D29: Production | E29: thousand metric tons | F29: 2023 | G29: 3938 | H29: xx
A30: Boron | B30: World total | C30: Boron all types | D30: Production | E30: thousand metric tons | F30: 2024 | G30: 4570 | H30: xx
A31: Boron | B31: World total | C31: Boron all types | D31: Reserves | E31: thousand metric tons | F31: 2024 | G31: 1086100 | H31: xx
A32: Bromine | B32: World total | C32: Production, bromine content, estimated | D32: Production | E32: metric tons | F32: 2024 | G32: 400000 | H32: Excludes U.S. production
A33: Bromine | B33: World total | C33: Production, bromine content, estimated | D33: Production | E33: metric tons | F33: 2023 | G33: 395000 | H33: Excludes U.S. production
A34: Cadmium | B34: World total | C34: Refinery production, estimated | D34: Production | E34: metric tons | F34: 2023 | G34: 24100
A35: Cadmium | B35: World total | C35: Refinery production, estimated | D35: Production | E35: metric tons | F35: 2024 | G35: 24000
A36: Cement | B36: World total | C36: Cement production, estimated | D36: Production | E36: thousand metric tons | F36: 2024 | G36: 4000000
A37: Cement | B37: World total | C37: Clinker capacity, estimated | D37: Production | E37: thousand metric tons | F37: 2024 | G37: 3800000
A38: Cement | B38: World total | C38: Cement production, estimated | D38: Production | E38: thousand metric tons | F38: 2023 | G38: 4100000
A39: Cement | B39: World total | C39: Clinker capacity, estimated | D39: Production | E39: thousand metric tons | F39: 2023 | G39: 3800000
A40: Chromium | B40: World total | C40: Mine production, grosss weight, marketable chromite ore | D40: Production | E40: thousand metric tons | F40: 2024 | G40: 47000
...

Sheet MYB
A1: SOURCE | B1: COMMODITY | C1: COUNTRY | D1: YEAR | E1: TYPE | F1: SUBTYPE | G1: UNIT | H1: VALUE | I1: COMMENT
A2: Mineral yearbook | B2: Aluminum | C2: World | D2: 2021 | E2: Smelter production | F2: Primary | G2: kt | H2: 67500 | I2: Primary aluminum is defined as “The weight of liquid aluminum as tapped from pots, excluding the weight of any alloying materials as well as that of any metal produced from either returned scrap of remelted material.” International reporting practices vary from country to country, some nations conforming to the foregoing definition and others using different definitions. For those countries for which a different definition is given specifically in the source publication, the definition is provided in a footnote.
A3: Mineral yearbook | B3: Chromium | C3: World | D3: 2023 | E3: Smelter production | F3: Total | G3: kt | H3: 15700 | I3: Ferrochromium
A4: Mineral yearbook | B4: Cobalt | C4: World | D4: 2023 | E4: Refinery production | F4: Total | G4: t | H4: 180000 | I4: tons, cobalt content. Figures represent cobalt refined from ores, concentrates, or intermediate products and do not include production of downstream products from refined cobalt.
A5: Mineral yearbook | B5: Cobalt | C5: World | D5: 2023 | E5: Mine production | F5: Total | G5: t | H5: 238000 | I5: tons, cobalt content. Figures represent recoverable cobalt content from ores, concentrates, or intermediate products from cobalt, copper, nickel, platinum, or zinc operations
A6: Mineral yearbook | B6: Copper | C6: World | D6: 2020 | E6: Mine production | F6: Total | G6: t | H6: 20600000 | I6: tons, copper content
A7: Mineral yearbook | B7: Copper | C7: World | D7: 2020 | E7: Mine production | F7: Total|Concentrates | G7: t | H7: 16400000 | I7: tons, copper content
A8: Mineral yearbook | B8: Copper | C8: World | D8: 2020 | E8: Mine production | F8: Total|Leaching, electrowon | G8: t | H8: 4190000 | I8: tons, copper content
A9: Mineral yearbook | B9: Copper | C9: World | D9: 2020 | E9: Smelter production | F9: Total | G9: t | H9: 21200000 | I9: tons, copper content
A10: Mineral yearbook | B10: Copper | C10: World | D10: 2020 | E10: Smelter production | F10: Total|Primary | G10: t | H10: 17800000 | I10: tons, copper content
A11: Mineral yearbook | B11: Copper | C11: World | D11: 2020 | E11: Smelter production | F11: Total|Secondary | G11: t | H11: 3390000 | I11: tons, copper content
A12: Mineral yearbook | B12: Copper | C12: World | D12: 2020 | E12: Refinery production | F12: Total | G12: t | H12: 25000000
A13: Mineral yearbook | B13: Copper | C13: World | D13: 2020 | E13: Refinery production | F13: Total|Primary | G13: t | H13: 21100000
A14: Mineral yearbook | B14: Copper | C14: World | D14: 2020 | E14: Refinery production | F14: Total|Primary|Leaching, electrowon | G14: t | H14: 4190000
A15: Mineral yearbook | B15: Copper | C15: World | D15: 2020 | E15: Refinery production | F15: Total|Primary|Other | G15: t | H15: 16900000
A16: Mineral yearbook | B16: Copper | C16: World | D16: 2020 | E16: Refinery production | F16: Total|Secondary | G16: t | H16: 3970000
A17: Mineral yearbook | B17: Ferromanganese | C17: World | D17: 2022 | E17: Smelter production | F17: Total | G17: t | H17: 5080000
A18: Mineral yearbook | B18: Graphite | C18: World | D18: 2022 | E18: Mine production | F18: Total | G18: t | H18: 1680000 | I18: Refers to natural graphite
A19: Mineral yearbook | B19: Graphite | C19: World | D19: 2022 | E19: Mine production | F19: Total|Amorphous | G19: t | H19: 208000 | I19: Refers to natural graphite
A20: Mineral yearbook | B20: Graphite | C20: World | D20: 2022 | E20: Mine production | F20: Total|Crystalline flake | G20: t | H20: 1470000 | I20: Refers to natural graphite
A21: Mineral yearbook | B21: Graphite | C21: World | D21: 2022 | E21: Mine production | F21: Total|Vein or lump | G21: t | H21: 3300 | I21: Refers to natural graphite
A22: Mineral yearbook | B22: Iridium | C22: World | D22: 2023 | E22: Mine production | F22: Total | G22: kg | H22: 7060
A23: Mineral yearbook | B23: Lead | C23: World | D23: 2022 | E23: Refinery production | F23: Total | G23: t | H23: 11900000
A24: Mineral yearbook | B24: Lead | C24: World | D24: 2022 | E24: Refinery production | F24: Total|Primary | G24: t | H24: 4250000
A25: Mineral yearbook | B25: Lead | C25: World | D25: 2022 | E25: Refinery production | F25: Total|Secondary | G25: t | H25: 7430000
A26: Mineral yearbook | B26: Lead | C26: World | D26: 2022 | E26: Refinery production | F26: Total|Undifferentiated | G26: t | H26: 272000
A27: Mineral yearbook | B27: Lead | C27: World | D27: 2022 | E27: Mine production | F27: Total | G27: t | H27: 4460000 | I27: tons, lead content
A28: Mineral yearbook | B28: Nickel | C28: World | D28: 2021 | E28: Refinery production | F28: Total | G28: t | H28: 2560000 | I28: tons, nickel content. Primary nickel refers to a nickel product ready for use by downstream consuming industries such as nickel chemicals and salts, ferronickel, nickel metal in various forms, nickel oxide sinter, and nickel pig iron. The USGS does not use the terms class I and class II nickel as defined by the International Nickel Study Group (INSG). However, nickel metal reported here is generally equivalent to Class I nickel which is defined by INSG as nickel with a mininum nickel content of 99% in the form of briquets, cathodes (i.e., electrolytic nickel), flakes or powders, granules, pellets, and rondelles. Ferronickel, nickel oxide sinter, and nickel pig iron are classified by INSG as Class II. Chemicals, although typically produced at refineries, are differentiated from production of metal when feasible. Several countries produced nickel-containing matte and other intermediates, but output of nickel in such materials has been excluded from this table to avoid double counting
A29: Mineral yearbook | B29: Nickel | C29: World | D29: 2021 | E29: Refinery production | F29: Total|Chemicals | G29: t | H29: 117000 | I29: tons, nickel content. Primary nickel refers to a nickel product ready for use by downstream consuming industries such as nickel chemicals and salts, ferronickel, nickel metal in various forms, nickel oxide sinter, and nickel pig iron. The USGS does not use the terms class I and class II nickel as defined by the International Nickel Study Group (INSG). However, nickel metal reported here is generally equivalent to Class I nickel which is defined by INSG as nickel with a mininum nickel content of 99% in the form of briquets, cathodes (i.e., electrolytic nickel), flakes or powders, granules, pellets, and rondelles. Ferronickel, nickel oxide sinter, and nickel pig iron are classified by INSG as Class II. Chemicals, although typically produced at refineries, are differentiated from production of metal when feasible. Several countries produced nickel-containing matte and other intermediates, but output of nickel in such materials has been excluded from this table to avoid double counting
A30: Mineral yearbook | B30: Nickel | C30: World | D30: 2021 | E30: Refinery production | F30: Total|Ferronickel | G30: t | H30: 1570000 | I30: tons, nickel content. Primary nickel refers to a nickel product ready for use by downstream consuming industries such as nickel chemicals and salts, ferronickel, nickel metal in various forms, nickel oxide sinter, and nickel pig iron. The USGS does not use the terms class I and class II nickel as defined by the International Nickel Study Group (INSG). However, nickel metal reported here is generally equivalent to Class I nickel which is defined by INSG as nickel with a mininum nickel content of 99% in the form of briquets, cathodes (i.e., electrolytic nickel), flakes or powders, granules, pellets, and rondelles. Ferronickel, nickel oxide sinter, and nickel pig iron are classified by INSG as Class II. Chemicals, although typically produced at refineries, are differentiated from production of metal when feasible. Several countries produced nickel-containing matte and other intermediates, but output of nickel in such materials has been excluded from this table to avoid double counting
A31: Mineral yearbook | B31: Nickel | C31: World | D31: 2021 | E31: Refinery production | F31: Total|Metal | G31: t | H31: 695000 | I31: tons, nickel content. Primary nickel refers to a nickel product ready for use by downstream consuming industries such as nickel chemicals and salts, ferronickel, nickel metal in various forms, nickel oxide sinter, and nickel pig iron. The USGS does not use the terms class I and class II nickel as defined by the International Nickel Study Group (INSG). However, nickel metal reported here is generally equivalent to Class I nickel which is defined by INSG as nickel with a mininum nickel content of 99% in the form of briquets, cathodes (i.e., electrolytic nickel), flakes or powders, granules, pellets, and rondelles. Ferronickel, nickel oxide sinter, and nickel pig iron are classified by INSG as Class II. Chemicals, although typically produced at refineries, are differentiated from production of metal when feasible. Several countries produced nickel-containing matte and other intermediates, but output of nickel in such materials has been excluded from this table to avoid double counting
A32: Mineral yearbook | B32: Nickel | C32: World | D32: 2021 | E32: Refinery production | F32: Total|Oxide sinter | G32: t | H32: 65900 | I32: tons, nickel content. Primary nickel refers to a nickel product ready for use by downstream consuming industries such as nickel chemicals and salts, ferronickel, nickel metal in various forms, nickel oxide sinter, and nickel pig iron. The USGS does not use the terms class I and class II nickel as defined by the International Nickel Study Group (INSG). However, nickel metal reported here is generally equivalent to Class I nickel which is defined by INSG as nickel with a mininum nickel content of 99% in the form of briquets, cathodes (i.e., electrolytic nickel), flakes or powders, granules, pellets, and rondelles. Ferronickel, nickel oxide sinter, and nickel pig iron are classified by INSG as Class II. Chemicals, although typically produced at refineries, are differentiated from production of metal when feasible. Several countries produced nickel-containing matte and other intermediates, but output of nickel in such materials has been excluded from this table to avoid double counting
A33: Mineral yearbook | B33: Nickel | C33: World | D33: 2021 | E33: Refinery production | F33: Total|Unspecified | G33: t | H33: 109000 | I33: tons, nickel content. Primary nickel refers to a nickel product ready for use by downstream consuming industries such as nickel chemicals and salts, ferronickel, nickel metal in various forms, nickel oxide sinter, and nickel pig iron. The USGS does not use the terms class I and class II nickel as defined by the International Nickel Study Group (INSG). However, nickel metal reported here is generally equivalent to Class I nickel which is defined by INSG as nickel with a mininum nickel content of 99% in the form of briquets, cathodes (i.e., electrolytic nickel), flakes or powders, granules, pellets, and rondelles. Ferronickel, nickel oxide sinter, and nickel pig iron are classified by INSG as Class II. Chemicals, although typically produced at refineries, are differentiated from production of metal when feasible. Several countries produced nickel-containing matte and other intermediates, but output of nickel in such materials has been excluded from this table to avoid double counting
A34: Mineral yearbook | B34: Nickel | C34: World | D34: 2021 | E34: Mine production | F34: Total | G34: t | H34: 2730000 | I34: tons, nickel content
A35: Mineral yearbook | B35: Nickel | C35: World | D35: 2021 | E35: Mine production | F35: Total|Laterial ore | G35: t | H35: 1920000 | I35: tons, nickel content
A36: Mineral yearbook | B36: Nickel | C36: World | D36: 2021 | E36: Mine production | F36: Total|Sulfide ore | G36: t | H36: 405000 | I36: tons, nickel content
A37: Mineral yearbook | B37: Nickel | C37: World | D37: 2021 | E37: Mine production | F37: Total|Other | G37: t | H37: 404000 | I37: tons, nickel content
A38: Mineral yearbook | B38: Palladium | C38: World | D38: 2023 | E38: Mine production | F38: Total | G38: kg | H38: 208000
A39: Mineral yearbook | B39: Palladium | C39: World | D39: 2023 | E39: Refinery production | F39: Total | G39: kg | H39: 322000
A40: Mineral yearbook | B40: Platinum | C40: World | D40: 2023 | E40: Refinery production | F40: Total | G40: kg | H40: 274000 | I40: Platinum content. Platinum-group metal primary refinery production only. Secondary production not included unless otherwise specified.
...

Sheet MCS25_raw
A1: SOURCE | B1: COMMODITY | C1: COUNTRY | D1: TYPE | E1: UNIT_MEAS | F1: PROD_2023 | G1: PROD_EST_ 2024 | H1: PROD_NOTES | I1: CAP_2023 | J1: CAP_EST_ 2024 | K1: CAP_NOTES | L1: RESERVES_2024 | M1: RESERVE_NOTES
A2: MCS2025 | B2: Abrasives | C2: United States | D2: Plant capacity, fused aluminum oxide | E2: metric tons | H2: estimated for 2023
A3: MCS2025 | B3: Abrasives | C3: United States and Canada | D3: Plant capacity, fused aluminum oxide | E3: metric tons | I3: 60000 | J3: 60000
A4: MCS2025 | B4: Abrasives | C4: Australia | D4: Plant capacity, fused aluminum oxide | E4: metric tons | I4: 50000 | J4: 50000
A5: MCS2025 | B5: Abrasives | C5: Austria | D5: Plant capacity, fused aluminum oxide | E5: metric tons | I5: 90000 | J5: 90000
A6: MCS2025 | B6: Abrasives | C6: Brazil | D6: Plant capacity, fused aluminum oxide | E6: metric tons | I6: 50000 | J6: 50000
A7: MCS2025 | B7: Abrasives | C7: China | D7: Plant capacity, fused aluminum oxide | E7: metric tons | I7: 800000 | J7: 800000
A8: MCS2025 | B8: Abrasives | C8: France | D8: Plant capacity, fused aluminum oxide | E8: metric tons | I8: 40000 | J8: 40000
A9: MCS2025 | B9: Abrasives | C9: Germany | D9: Plant capacity, fused aluminum oxide | E9: metric tons | I9: 80000 | J9: 80000
