Workbook

Sheet README
A1: Title of the article: "Metals for the Energy Transition: A Heavy Environmental Burden to Life?"
A2: Authors: Anne de Bortoli, Marin Pellan, Marguerite Fauroux
A3: Affiliations:
A4: Journal: Joule
A7: TAB_NAME | B7: DESCRIPTION | C7: SOURCE
A8: IEA_demand | B8: List of 37 metals in the 2024 version with details per technology when available. Data is given in kt. | C8: https://www.iea.org/data-and-statistics/data-tools/critical-minerals-data-explorer https://www.iea.org/data-and-statistics/data-product/critical-minerals-dataset
A9: IEA_demand_old | B9: Old list of x metals extracted in January 2024. Data is given in kt. | C9: x
A10: EI_MARKETS | B10: Associated ecoinvent 3.10 activities for each metals and technology. | C10: x

Sheet metal_list
A1: Z | B1: Symbol | C1: Metal | D1: Category | E1: Subcategory
A2: 13 | B2: Al | C2: Aluminium
A3: 33 | B3: As | C3: Arsenic
A4: 5 | B4: B | C4: Boron
A5: 48 | B5: Cd | C5: Cadmium
A6: 24 | B6: Cr | C6: Chromium
A7: 27 | B7: Co | C7: Cobalt
A8: 29 | B8: Cu | C8: Copper
A9: 66 | B9: Dy | C9: Dysprosium | D9: REE
A10: 31 | B10: Ga | C10: Gallium
A11: 32 | B11: Ge | C11: Germanium
A12: 6 | B12: C | C12: Graphite (battery-grade)
A13: 72 | B13: Hf | C13: Hafnium
A14: 49 | B14: In | C14: Indium
A15: 77 | B15: Ir | C15: Iridium | D15: PGM
A16: 57 | B16: La | C16: Lanthanum | D16: REE
A17: 82 | B17: Pb | C17: Lead
A18: 3 | B18: Li | C18: Lithium
A19: 12 | B19: Mg | C19: Magnesium
A20: 25 | B20: Mn | C20: Manganese
A21: 42 | B21: Mo | C21: Molybdenum
A22: 60 | B22: Nd | C22: Neodymium | D22: REE
A23: 28 | B23: Ni | C23: Nickel
A24: 41 | B24: Nb | C24: Niobium
A25: x | B25: x | C25: PGMs (other than iridum) | D25: PGM | E25: Thus contains: Ruthenium, Rhodium Palladium, Osmium and Platinum
A26: 59 | B26: Pr | C26: Praseodymium | D26: REE
A27: 34 | B27: Se | C27: Selenium
A28: 14 | B28: Si | C28: Silicon
A29: 47 | B29: Ag | C29: Silver
A30: 73 | B30: Ta | C30: Tantalum
A31: 52 | B31: Te | C31: Tellurium
A32: 65 | B32: Tb | C32: Terbium | D32: REE
A33: 50 | B33: Sn | C33: Tin
A34: 22 | B34: Ti | C34: Titanium
A35: 74 | B35: W | C35: Tungsten
A36: 23 | B36: V | C36: Vanadium
A37: 39 | B37: Y | C37: Yttrium | D37: REE
A38: 30 | B38: Zn | C38: Zinc
A39: 40 | B39: Zr | C39: Zirconium

Sheet EI_markets_etm
A1: Metal | B1: Technology | C1: Market | D1: Reference Product | E1: Location | F1: Scenario | G1: 2022 | H1: 2030 | I1: 2035 | J1: 2040 | K1: 2045 | L1: 2050
A2: Aluminium | B2: Electricity Networks | C2: market for aluminium, wrought alloy (SM) | D2: aluminium, wrought alloy | E2: World | F2: SPS | G2: =IEA_demand!D2 -> 10773.333 | H2: =IEA_demand!E2 -> 14527 | I2: =IEA_demand!F2 -> 14482 | J2: =IEA_demand!G2 -> 14174 | K2: =IEA_demand!H2 -> 14943 | L2: =IEA_demand!I2 -> 14343
A3: Aluminium | B3: Electricity Networks | C3: market for aluminium, wrought alloy (SM) | D3: aluminium, wrought alloy | E3: World | F3: NZE | G3: =IEA_demand!D3 -> 11045.667 | H3: =IEA_demand!E3 -> 17872 | I3: =IEA_demand!F3 -> 22818 | J3: =IEA_demand!G3 -> 26403 | K3: =IEA_demand!H3 -> 25148 | L3: =IEA_demand!I3 -> 20759
A4: Arsenic | B4: Solar PV | C4: market for arsine | D4: arsine | E4: GLO | F4: SPS | G4: =IEA_demand!D4 -> 0 | H4: =IEA_demand!E4 -> 0.343221 | I4: =IEA_demand!F4 -> 1.97674 | J4: =IEA_demand!G4 -> 10.9458 | K4: =IEA_demand!H4 -> 11.4615 | L4: =IEA_demand!I4 -> 12.5651
A5: Arsenic | B5: Solar PV | C5: market for arsine | D5: arsine | E5: GLO | F5: NZE | G5: =IEA_demand!D5 -> 0 | H5: =IEA_demand!E5 -> 0.551123 | I5: =IEA_demand!F5 -> 3.22612 | J5: =IEA_demand!G5 -> 15.2916 | K5: =IEA_demand!H5 -> 12.4686 | L5: =IEA_demand!I5 -> 15.8108
A6: Boron | B6: Wind | C6: market for boric oxide | D6: boric oxide | E6: GLO | F6: SPS | G6: =IEA_demand!D6 -> 0.206005 | H6: =IEA_demand!E6 -> 0.401025 | I6: =IEA_demand!F6 -> 0.349539 | J6: =IEA_demand!G6 -> 0.292967 | K6: =IEA_demand!H6 -> 0.331853 | L6: =IEA_demand!I6 -> 0.466954
A7: Boron | B7: Wind | C7: market for boric oxide | D7: boric oxide | E7: GLO | F7: NZE | G7: =IEA_demand!D7 -> 0.206005 | H7: =IEA_demand!E7 -> 0.705002 | I7: =IEA_demand!F7 -> 0.706441 | J7: =IEA_demand!G7 -> 0.625155 | K7: =IEA_demand!H7 -> 0.611907 | L7: =IEA_demand!I7 -> 0.86571
A8: Cadmium | B8: Solar PV | C8: market for cadmium, semiconductor-grade | D8: cadmium, semiconductor-grade | E8: GLO | F8: SPS | G8: =IEA_demand!D8 -> 0.67 | H8: =IEA_demand!E8 -> 0.66 | I8: =IEA_demand!F8 -> 0.68 | J8: =IEA_demand!G8 -> 0.67 | K8: =IEA_demand!H8 -> 0.68 | L8: =IEA_demand!I8 -> 0.72
A9: Cadmium | B9: Solar PV | C9: market for cadmium, semiconductor-grade | D9: cadmium, semiconductor-grade | E9: GLO | F9: NZE | G9: =IEA_demand!D9 -> 0.67 | H9: =IEA_demand!E9 -> 1.49 | I9: =IEA_demand!F9 -> 1.42 | J9: =IEA_demand!G9 -> 1.03 | K9: =IEA_demand!H9 -> 0.65 | L9: =IEA_demand!I9 -> 0.52
A10: Cadmium | B10: Other low emissions power generation | C10: market for cadmium, semiconductor-grade | D10: cadmium, semiconductor-grade | E10: GLO | F10: SPS | G10: =IEA_demand!D10 -> 0.02 | H10: =IEA_demand!E10 -> 0.03 | I10: =IEA_demand!F10 -> 0.02 | J10: =IEA_demand!G10 -> 0.01 | K10: =IEA_demand!H10 -> 0.02 | L10: =IEA_demand!I10 -> 0.02
A11: Cadmium | B11: Other low emissions power generation | C11: market for cadmium, semiconductor-grade | D11: cadmium, semiconductor-grade | E11: GLO | F11: NZE | G11: =IEA_demand!D11 -> 0.02 | H11: =IEA_demand!E11 -> 0.03 | I11: =IEA_demand!F11 -> 0.03 | J11: =IEA_demand!G11 -> 0.03 | K11: =IEA_demand!H11 -> 0.02 | L11: =IEA_demand!I11 -> 0.02
A12: Chromium | B12: Wind | C12: market for ferrochromium, high-carbon, 68% Cr | D12: ferrochromium, high-carbon, 68% Cr | E12: GLO | F12: SPS | G12: =IEA_demand!D14 -> 63.2737 | H12: =IEA_demand!E14 -> 88.4126 | I12: =IEA_demand!F14 -> 78.8923 | J12: =IEA_demand!G14 -> 69.5036 | K12: =IEA_demand!H14 -> 77.4518 | L12: =IEA_demand!I14 -> 97.3744
A13: Chromium | B13: Wind | C13: market for ferrochromium, high-carbon, 68% Cr | D13: ferrochromium, high-carbon, 68% Cr | E13: GLO | F13: NZE | G13: =IEA_demand!D15 -> 63.2737 | H13: =IEA_demand!E15 -> 154.914 | I13: =IEA_demand!F15 -> 167.174 | J13: =IEA_demand!G15 -> 146.251 | K13: =IEA_demand!H15 -> 126.206 | L13: =IEA_demand!I15 -> 160.709
A14: Chromium | B14: Other low emissions power generation | C14: market for ferrochromium, high-carbon, 68% Cr | D14: ferrochromium, high-carbon, 68% Cr | E14: GLO | F14: SPS | G14: =IEA_demand!D16 -> 148.7563 | H14: =IEA_demand!E16 -> 295.4034 | I14: =IEA_demand!F16 -> 222.6017 | J14: =IEA_demand!G16 -> 246.7724 | K14: =IEA_demand!H16 -> 250.2902 | L14: =IEA_demand!I16 -> 224.6666
A15: Chromium | B15: Other low emissions power generation | C15: market for ferrochromium, high-carbon, 68% Cr | D15: ferrochromium, high-carbon, 68% Cr | E15: GLO | F15: NZE | G15: =IEA_demand!D17 -> 148.7563 | H15: =IEA_demand!E17 -> 668.829 | I15: =IEA_demand!F17 -> 584.868 | J15: =IEA_demand!G17 -> 480.945 | K15: =IEA_demand!H17 -> 379.97 | L15: =IEA_demand!I17 -> 299.482
A16: Cobalt | B16: Low emissions power generation | C16: market for cobalt sulfate (SM) | D16: cobalt sulfate | E16: World | F16: SPS | G16: =IEA_demand!D20 -> 0.0164945 | H16: =IEA_demand!E20 -> 0.0288952 | I16: =IEA_demand!F20 -> 0.0135566 | J16: =IEA_demand!G20 -> 0.0161804 | K16: =IEA_demand!H20 -> 0.0171346 | L16: =IEA_demand!I20 -> 0.0197795
A17: Cobalt | B17: Low emissions power generation | C17: market for cobalt sulfate (SM) | D17: cobalt sulfate | E17: World | F17: NZE | G17: =IEA_demand!D21 -> 0.0164945 | H17: =IEA_demand!E21 -> 0.0512678 | I17: =IEA_demand!F21 -> 0.0468942 | J17: =IEA_demand!G21 -> 0.0364758 | K17: =IEA_demand!H21 -> 0.0278917 | L17: =IEA_demand!I21 -> 0.0253343
A18: Cobalt | B18: Electric vehicles | C18: market for cobalt sulfate (SM) | D18: cobalt sulfate | E18: World | F18: SPS | G18: =IEA_demand!D22 -> 61.8409 | H18: =IEA_demand!E22 -> 150.718 | I18: =IEA_demand!F22 -> 160.685 | J18: =IEA_demand!G22 -> 187.206 | K18: =IEA_demand!H22 -> 203.124 | L18: =IEA_demand!I22 -> 216.036
A19: Cobalt | B19: Electric vehicles | C19: market for cobalt sulfate (SM) | D19: cobalt sulfate | E19: World | F19: NZE | G19: =IEA_demand!D23 -> 61.8409 | H19: =IEA_demand!E23 -> 236.409 | I19: =IEA_demand!F23 -> 247.364 | J19: =IEA_demand!G23 -> 278.864 | K19: =IEA_demand!H23 -> 313.127 | L19: =IEA_demand!I23 -> 322.573
A20: Cobalt | B20: Grid battery storage | C20: market for cobalt sulfate (SM) | D20: cobalt sulfate | E20: World | F20: SPS | G20: =IEA_demand!D24 -> 2.52783 | H20: =IEA_demand!E24 -> 4.13446 | I20: =IEA_demand!F24 -> 3.26534 | J20: =IEA_demand!G24 -> 0 | K20: =IEA_demand!H24 -> 0 | L20: =IEA_demand!I24 -> 0
A21: Cobalt | B21: Grid battery storage | C21: market for cobalt sulfate (SM) | D21: cobalt sulfate | E21: World | F21: NZE | G21: =IEA_demand!D25 -> 2.52783 | H21: =IEA_demand!E25 -> 6.63385 | I21: =IEA_demand!F25 -> 5.56078 | J21: =IEA_demand!G25 -> 0 | K21: =IEA_demand!H25 -> 0 | L21: =IEA_demand!I25 -> 0
A22: Cobalt | B22: Hydrogen technologies | C22: market for cobalt sulfate (SM) | D22: cobalt sulfate | E22: World | F22: SPS | G22: =IEA_demand!D26 -> 0.00511403 | H22: =IEA_demand!E26 -> 0.00409554 | I22: =IEA_demand!F26 -> 0.00451973 | J22: =IEA_demand!G26 -> 0.00356799 | K22: =IEA_demand!H26 -> 0.00343121 | L22: =IEA_demand!I26 -> 0.00469507
A23: Cobalt | B23: Hydrogen technologies | C23: market for cobalt sulfate (SM) | D23: cobalt sulfate | E23: World | F23: NZE | G23: =IEA_demand!D27 -> 0.00511403 | H23: =IEA_demand!E27 -> 0.0642585 | I23: =IEA_demand!F27 -> 0.0697531 | J23: =IEA_demand!G27 -> 0.0595121 | K23: =IEA_demand!H27 -> 0.0510738 | L23: =IEA_demand!I27 -> 0.0659947
A24: Copper | B24: Solar PV | C24: market for copper, cathode (SM) | D24: copper, cathode | E24: World | F24: SPS | G24: =IEA_demand!D30 -> 1208.23 | H24: =IEA_demand!E30 -> 1691.18 | I24: =IEA_demand!F30 -> 1727.66 | J24: =IEA_demand!G30 -> 1683.97 | K24: =IEA_demand!H30 -> 1772.88 | L24: =IEA_demand!I30 -> 1958.85
A25: Copper | B25: Solar PV | C25: market for copper, cathode (SM) | D25: copper, cathode | E25: World | F25: NZE | G25: =IEA_demand!D31 -> 1208.23 | H25: =IEA_demand!E31 -> 2564.33 | I25: =IEA_demand!F31 -> 2651.29 | J25: =IEA_demand!G31 -> 2245.3 | K25: =IEA_demand!H31 -> 1840.51 | L25: =IEA_demand!I31 -> 2390.46
A26: Copper | B26: Wind | C26: market for copper, cathode (SM) | D26: copper, cathode | E26: World | F26: SPS | G26: =IEA_demand!D32 -> 501.618 | H26: =IEA_demand!E32 -> 803.565 | I26: =IEA_demand!F32 -> 691.799 | J26: =IEA_demand!G32 -> 579.893 | K26: =IEA_demand!H32 -> 626.262 | L26: =IEA_demand!I32 -> 804.512
A27: Copper | B27: Wind | C27: market for copper, cathode (SM) | D27: copper, cathode | E27: World | F27: NZE | G27: =IEA_demand!D33 -> 501.618 | H27: =IEA_demand!E33 -> 1419.33 | I27: =IEA_demand!F33 -> 1445.27 | J27: =IEA_demand!G33 -> 1242.85 | K27: =IEA_demand!H33 -> 1107.76 | L27: =IEA_demand!I33 -> 1451.29
A28: Copper | B28: Other low emissions power generation | C28: market for copper, cathode (SM) | D28: copper, cathode | E28: World | F28: SPS | G28: =IEA_demand!D34 -> 82.822 | H28: =IEA_demand!E34 -> 123.155 | I28: =IEA_demand!F34 -> 80.941 | J28: =IEA_demand!G34 -> 82.857 | K28: =IEA_demand!H34 -> 107.788 | L28: =IEA_demand!I34 -> 103.818
A29: Copper | B29: Other low emissions power generation | C29: market for copper, cathode (SM) | D29: copper, cathode | E29: World | F29: NZE | G29: =IEA_demand!D35 -> 82.822 | H29: =IEA_demand!E35 -> 229.27 | I29: =IEA_demand!F35 -> 222.86 | J29: =IEA_demand!G35 -> 183.05 | K29: =IEA_demand!H35 -> 150.51 | L29: =IEA_demand!I35 -> 130.46
A30: Copper | B30: Electric vehicles | C30: market for copper, cathode (SM) | D30: copper, cathode | E30: World | F30: SPS | G30: =IEA_demand!D36 -> 395.95 | H30: =IEA_demand!E36 -> 1644.59 | I30: =IEA_demand!F36 -> 2594.14 | J30: =IEA_demand!G36 -> 3131.08 | K30: =IEA_demand!H36 -> 3286.87 | L30: =IEA_demand!I36 -> 3470.4
A31: Copper | B31: Electric vehicles | C31: market for copper, cathode (SM) | D31: copper, cathode | E31: World | F31: NZE | G31: =IEA_demand!D37 -> 395.95 | H31: =IEA_demand!E37 -> 2611.54 | I31: =IEA_demand!F37 -> 4028.1 | J31: =IEA_demand!G37 -> 4642.25 | K31: =IEA_demand!H37 -> 5043.91 | L31: =IEA_demand!I37 -> 5123.73
A32: Copper | B32: Grid battery storage | C32: market for copper, cathode (SM) | D32: copper, cathode | E32: World | F32: SPS | G32: =IEA_demand!D38 -> 39.5966 | H32: =IEA_demand!E38 -> 175.747 | I32: =IEA_demand!F38 -> 260.282 | J32: =IEA_demand!G38 -> 380.677 | K32: =IEA_demand!H38 -> 454.317 | L32: =IEA_demand!I38 -> 544.674
A33: Copper | B33: Grid battery storage | C33: market for copper, cathode (SM) | D33: copper, cathode | E33: World | F33: NZE | G33: =IEA_demand!D39 -> 39.5966 | H33: =IEA_demand!E39 -> 281.99 | I33: =IEA_demand!F39 -> 443.253 | J33: =IEA_demand!G39 -> 654.388 | K33: =IEA_demand!H39 -> 745.109 | L33: =IEA_demand!I39 -> 897.638
A34: Copper | B34: Electricity networks | C34: market for copper, cathode (SM) | D34: copper, cathode | E34: World | F34: SPS | G34: =IEA_demand!D40 -> 4143.48 | H34: =IEA_demand!E40 -> 6103.96 | I34: =IEA_demand!F40 -> 6168.15 | J34: =IEA_demand!G40 -> 6125.22 | K34: =IEA_demand!H40 -> 6312.07 | L34: =IEA_demand!I40 -> 6084.43
A35: Copper | B35: Electricity networks | C35: market for copper, cathode (SM) | D35: copper, cathode | E35: World | F35: NZE | G35: =IEA_demand!D41 -> 4143.48 | H35: =IEA_demand!E41 -> 7939.65 | I35: =IEA_demand!F41 -> 9793.41 | J35: =IEA_demand!G41 -> 10510.1 | K35: =IEA_demand!H41 -> 10437.8 | L35: =IEA_demand!I41 -> 9245.51
... A37: Copper | B37: Hydrogen technologies | C37: market for copper, cathode (SM) | D37: copper, cathode | E37: World | F37: NZE | G37: =IEA_demand!D43 -> 0.00212289 | H37: =IEA_demand!E43 -> 0.187135 | I37: =IEA_demand!F43 -> 0.203227 | J37: =IEA_demand!G43 -> 0.173466 | K37: =IEA_demand!H43 -> 0.148932 | L37: =IEA_demand!I43 -> 0.19252
A38: Dysprosium | B38: Wind | C38: market for dysprosium oxide | D38: dysprosium oxide | E38: GLO | F38: SPS | G38: =IEA_demand!D46 -> 0.8 | H38: =IEA_demand!E46 -> 1.33 | I38: =IEA_demand!F46 -> 1.13 | J38: =IEA_demand!G46 -> 0.94 | K38: =IEA_demand!H46 -> 1.02 | L38: =IEA_demand!I46 -> 1.33
A39: Dysprosium | B39: Wind | C39: market for dysprosium oxide | D39: dysprosium oxide | E39: GLO | F39: NZE | G39: =IEA_demand!D47 -> 0.8 | H39: =IEA_demand!E47 -> 2.34 | I39: =IEA_demand!F47 -> 2.32 | J39: =IEA_demand!G47 -> 1.97 | K39: =IEA_demand!H47 -> 1.77 | L39: =IEA_demand!I47 -> 2.31
A40: Dysprosium | B40: Electric vehicles | C40: market for dysprosium oxide | D40: dysprosium oxide | E40: GLO | F40: SPS | G40: =IEA_demand!D48 -> 0.53 | H40: =IEA_demand!E48 -> 1.77 | I40: =IEA_demand!F48 -> 2.47 | J40: =IEA_demand!G48 -> 2.81 | K40: =IEA_demand!H48 -> 2.98 | L40: =IEA_demand!I48 -> 3.11
A41: Dysprosium | B41: Electric vehicles | C41: market for dysprosium oxide | D41: dysprosium oxide | E41: GLO | F41: NZE | G41: =IEA_demand!D49 -> 0.53 | H41: =IEA_demand!E49 -> 2.55 | I41: =IEA_demand!F49 -> 3.61 | J41: =IEA_demand!G49 -> 3.74 | K41: =IEA_demand!H49 -> 3.94 | L41: =IEA_demand!I49 -> 4.06
...

Sheet EI_markets_roe
A1: Metal | B1: Technology | C1: Market | D1: Reference Product | E1: Location | F1: Scenario | G1: 2022 | H1: 2030 | I1: 2035 | J1: 2040 | K1: 2045 | L1: 2050
A2: Aluminium | B2: Rest of the economy | C2: market for aluminium, wrought alloy (SM) | D2: aluminium, wrought alloy | E2: World | F2: NZE | G2: 100065.44 | H2: 121513.49 | I2: 137047.3 | J2: 153044.41 | K2: 170972.87 | L2: 189969.26
A3: Arsenic | B3: Rest of the economy | C3: market for arsine | D3: arsine | E3: GLO | F3: NZE | G3: 61.5 | H3: 74.681922 | I3: 84.228966 | J3: 94.060754 | K3: 105.07954 | L3: 116.75469
A4: Boron | B4: Rest of the economy | C4: market for boric oxide | D4: boric oxide | E4: GLO | F4: NZE | G4: 3055.682 | H4: 3710.6375 | I4: 4184.9908 | J4: 4673.4919 | K4: 5220.9702 | L4: 5801.0601
A5: Cadmium | B5: Rest of the economy | C5: market for cadmium, semiconductor-grade | D5: cadmium, semiconductor-grade | E5: GLO | F5: NZE | G5: 23.41 | H5: 28.427704 | I5: 32.06179 | J5: 35.804264 | K5: 39.998571 | L5: 44.442719
A6: Chromium | B6: Rest of the economy | C6: market for ferrochromium, high-carbon, 68% Cr | D6: ferrochromium, high-carbon, 68% Cr | E6: GLO | F6: NZE | G6: 15487.97 | H6: 18807.665 | I6: 21211.963 | J6: 23687.97 | K6: 26462.908 | L6: 29403.14
A7: Cobalt | B7: Rest of the economy | C7: market for cobalt sulfate (SM) | D7: cobalt sulfate | E7: World | F7: NZE | G7: 135.60966 | H7: 164.67626 | I7: 185.72783 | J7: 207.40727 | K7: 231.70409 | L7: 257.44819
A8: Copper | B8: Rest of the economy | C8: market for copper, cathode (SM) | D8: copper, cathode | E8: World | F8: NZE | G8: 20628.301 | H8: 25049.775 | I8: 28252.04 | J8: 31549.814 | K8: 35245.732 | L8: 39161.803
A9: Dysprosium | B9: Rest of the economy | C9: market for dysprosium oxide | D9: dysprosium oxide | E9: GLO | F9: NZE | G9: 0.046958942 | H9: 0.057024131 | I9: 0.064313872 | J9: 0.071821032 | K9: 0.08023454 | L9: 0.089149213
A10: Gallium | B10: Rest of the economy | C10: market for gallium, semiconductor-grade | D10: gallium, semiconductor-grade | E10: GLO | F10: NZE | G10: 0.6174461 | H10: 0.74978962 | I10: 0.84563978 | J10: 0.94434871 | K10: 1.0549749 | L10: 1.1721907
A11: Graphite | B11: Rest of the economy | C11: market for graphite, battery grade | D11: graphite, battery grade | E11: CN | F11: NZE | G11: 757.8174 | H11: 920.24813 | I11: 1037.889 | J11: 1159.0386 | K11: 1294.8147 | L11: 1438.6786
A12: Indium | B12: Rest of the economy | C12: market for indium | D12: indium | E12: GLO | F12: NZE | G12: 0.92 | H12: 1.117193 | I12: 1.2600105 | J12: 1.4070877 | K12: 1.5719216 | L12: 1.7465742
... A36: Zirconium | B36: Rest of the economy | C36: market for zirconium oxide | D36: zirconium oxide | E36: GLO | F36: NZE | G36: 1230.57 | H36: 1494.3306 | I36: 1685.36 | J36: 1882.0869 | K36: 2102.5648 | L36: 2336.1759

Sheet IEA_demand
A1: Metal | B1: Technology | C1: Scenario | D1: 2022 | E1: 2030 | F1: 2035 | G1: 2040 | H1: 2045 | I1: 2050
A2: Aluminium | B2: Electricity networks | C2: SPS | D2: 10773.333 | E2: 14527 | F2: 14482 | G2: 14174 | H2: 14943 | I2: 14343
A3: Aluminium | B3: Electricity networks | C3: NZE | D3: 11045.667 | E3: 17872 | F3: 22818 | G3: 26403 | H3: 25148 | I3: 20759
A4: Arsenic | B4: Solar PV | C4: SPS | D4: 0 | E4: 0.343221 | F4: 1.97674 | G4: 10.9458 | H4: 11.4615 | I4: 12.5651
A5: Arsenic | B5: Solar PV | C5: NZE | D5: 0 | E5: 0.551123 | F5: 3.22612 | G5: 15.2916 | H5: 12.4686 | I5: 15.8108
A6: Boron | B6: Wind | C6: SPS | D6: 0.206005 | E6: 0.401025 | F6: 0.349539 | G6: 0.292967 | H6: 0.331853 | I6: 0.466954
A7: Boron | B7: Wind | C7: NZE | D7: 0.206005 | E7: 0.705002 | F7: 0.706441 | G7: 0.625155 | H7: 0.611907 | I7: 0.86571
A8: Cadmium | B8: Solar PV | C8: SPS | D8: 0.67 | E8: 0.66 | F8: 0.68 | G8: 0.67 | H8: 0.68 | I8: 0.72
A9: Cadmium | B9: Solar PV | C9: NZE | D9: 0.67 | E9: 1.49 | F9: 1.42 | G9: 1.03 | H9: 0.65 | I9: 0.52
A10: Cadmium | B10: Other low emissions power generation | C10: SPS | D10: 0.02 | E10: 0.03 | F10: 0.02 | G10: 0.01 | H10: 0.02 | I10: 0.02
A11: Cadmium | B11: Other low emissions power generation | C11: NZE | D11: 0.02 | E11: 0.03 | F11: 0.03 | G11: 0.03 | H11: 0.02 | I11: 0.02
A12: Cadmium | B12: Total | C12: SPS | D12: 0.687649 | E12: 0.683595 | F12: 0.695917 | G12: 0.687914 | H12: 0.706137 | I12: 0.734046
... A199: Zirconium | B199: Total | C199: NZE | D199: 0.634481 | E199: 11.1363 | F199: 11.9887 | G199: 10.0979 | H199: 8.64033 | I199: 10.854

Sheet roe_demand

Sheet d
B1: Metal_proj | D1: Metal_ei
B2: Aluminium | D2: Aluminium | F2: 1
B3: Arsenic | D3: Arsenic | F3: 2
B4: Boron | D4: Boron | F4: 3
B5: Cadmium | D5: Cadmium | F5: 4
B6: Chromium | D6: Chromium | F6: 5
B7: Cobalt | D7: Cobalt | F7: 6 | I7: No technology for, to put in 'Other':
B8: Copper | D8: Copper | F8: 7 | I8: Hafnium
B9: Dysprosium | D9: Dysprosium | F9: 8 | I9: Lanthanum
B10: Gallium | D10: Ferromanganese | E10: Hypothesis made based on manganese | F10: 9 | I10: Magnesium
B11: Germanium | C11: No market in EI3.8? | D11: Ferronickel | E11: Hypothesis made based on nickel | F11: 10 | I11: Niobium
B12: Graphite | D12: Gallium | F12: 11 | I12: Tantalum
B13: Indium | D13: Graphite | F13: 12 | I13: Titanium
B14: Iridium | D14: Indium | F14: 13 | I14: Tungsten
B15: Lead | D15: Iridium | E15: Market for PGM is chosen | F15: 14
B16: Lithium | D16: Lead | F16: 15
B17: Manganese | D17: Lithium | F17: 16
B18: Molybdenum | D18: Manganese | F18: 17 | I18: No EI3.8 for:
B19: Neodymium | D19: Molybdenum | F19: 18 | I19: Germanium
B20: Nickel | D20: Neodymium | F20: 19 | I20: Iridium
B21: PGM | D21: Nickel | F21: 20 | I21: Vanadium
B22: Praseodymium | D22: Platinum | E22: Market for platinum is chosen | F22: 21
B23: Selenium | D23: Praseodymium | F23: 22
B24: Silicon | D24: Selenium | F24: 23
B25: Silver | D25: Silicon | F25: 24
B26: Tellurium | D26: Silver | F26: 25
B27: Terbium | D27: Tellurium | F27: 26
B28: Tin | D28: Terbium | F28: 27
B29: Vanadium | D29: Tin | F29: 28
B30: Yttrium | C30: No market in EI3.8? | D30: Vanadium | F30: 29
B31: Zinc | D31: Zinc | F31: 30
B32: Zirconium | D32: Zirconium | F32: 31

Sheet EI_markets_old
A1: Metal | B1: Technology | C1: Market | D1: Reference Product | E1: Location | F1: Scenario | G1: 2022 | H1: 2025 | I1: 2030 | J1: 2035 | K1: 2040 | L1: 2045 | M1: 2050
A2: Aluminium | B2: Electricity Networks | C2: market for aluminium, wrought alloy (SM) | D2: aluminium, wrought alloy | E2: World | F2: NZE | G2: 10357 | H2: 12423 | I2: 17872 | J2: 22818 | K2: 26403 | L2: 25148 | M2: 20759
A3: Aluminium | B3: Electricity Networks | C3: market for aluminium, wrought alloy (SM) | D3: aluminium, wrought alloy | E3: World | F3: SPS | G3: 10357 | H3: 11606 | I3: 14527 | J3: 14482 | K3: 14174 | L3: 14943 | M3: 14343
A4: Arsenic | B4: Solar PV | C4: market for arsine | D4: arsine | E4: GLO | F4: NZE | G4: 0 | H4: 0 | I4: 0.436136 | J4: 2.506 | K4: 13.8113 | L4: 11.2171 | M4: 12.5443
A5: Arsenic | B5: Solar PV | C5: market for arsine | D5: arsine | E5: GLO | F5: SPS | G5: 0 | H5: 0 | I5: 0.190329 | J5: 1.08483 | K5: 6.38179 | L5: 7.38525 | M5: 8.34983
A6: Boron | B6: Wind | C6: market for boric oxide | D6: boric oxide | E6: GLO | F6: NZE | G6: 0.158618 | H6: 0.282352 | I6: 0.73109 | J6: 0.72847 | K6: 0.691595 | L6: 0.472797 | M6: 0.746079
A7: Boron | B7: Wind | C7: market for boric oxide | D7: boric oxide | E7: GLO | F7: SPS | G7: 0.158618 | H7: 0.175778 | I7: 0.314919 | J7: 0.287788 | K7: 0.259729 | L7: 0.329544 | M7: 0.408226
A8: Cadmium | B8: Solar PV | C8: market for cadmium, semiconductor-grade | D8: cadmium, semiconductor-grade | E8: GLO | F8: NZE | G8: 0.420843 | H8: 0.770334 | I8: 1.22404 | J8: 1.13261 | K8: 0.954223 | L8: 0.598829 | M8: 0.431189
A9: Cadmium | B9: Solar PV | C9: market for cadmium, semiconductor-grade | D9: cadmium, semiconductor-grade | E9: GLO | F9: SPS | G9: 0.420843 | H9: 0.420292 | I9: 0.397562 | J9: 0.395331 | K9: 0.4115 | L9: 0.465976 | M9: 0.503529
A10: Chromium | B10: Wind | C10: market for ferrochromium, high-carbon, 68% Cr | D10: ferrochromium, high-carbon, 68% Cr | E10: GLO | F10: NZE | G10: 50.316 | H10: 90.7843 | I10: 194.749 | J10: 184.31 | K10: 150.32 | L10: 104.515 | M10: 155.083
A11: Chromium | B11: Wind | C11: market for ferrochromium, high-carbon, 68% Cr | D11: ferrochromium, high-carbon, 68% Cr | E11: GLO | F11: SPS | G11: 50.316 | H11: 54.1772 | I11: 72.675 | J11: 70.6757 | K11: 65.8656 | L11: 81.2922 | M11: 90.0715
A12: Cobalt | B12: Battery Storage | C12: market for cobalt sulfate (SM) | D12: cobalt sulfate | E12: World | F12: NZE | G12: 3.58853 | H12: 6.22965 | I12: 17.0211 | J12: 17.7203 | K12: 14.4376 | L12: 6.95082 | M12: 0
A13: Cobalt | B13: EV | C13: market for cobalt sulfate (SM) | D13: cobalt sulfate | E13: World | F13: NZE | G13: 64.5606 | H13: 130.418 | I13: 187.993 | J13: 230.828 | K13: 243.972 | L13: 278.214 | M13: 290.557
... A105: Zirconium | B105: Hydrogen | C105: market for zirconium oxide | D105: zirconium oxide | E105: GLO | F105: SPS | G105: 0.239703 | H105: 0.329434 | I105: 0.718836 | J105: 0.574094 | K105: 0.515841 | L105: 0.557571 | M105: 0.775065

Sheet IEA_demand_OLD
A1: Technology | B1: Detail | C1: Metal | D1: Scenario | E1: 2022 | F1: 2023 | G1: 2024 | H1: 2025 | I1: 2026 | J1: 2027 | K1: 2028 | L1: 2029 | M1: 2030 | N1: 2031 | O1: 2032 | P1: 2033 | Q1: 2034 | R1: 2035 | S1: 2036 | T1: 2037 | U1: 2038 | V1: 2039 | W1: 2040 | X1: 2041 | Y1: 2042 | Z1: 2043 | AA1: 2044 | AB1: 2045 | AC1: 2046 | AD1: 2047 | AE1: 2048 | AF1: 2049 | AG1: 2050 | AH1: cum_demand
A2: Electricity Networks | B2: Wire | C2: Aluminium | D2: SPS | E2: 10357 | F2: =(($H2-$E2)/($H$1-$E$1))*(F$1-$E$1)+$E2 -> 10773.333 | G2: =(($H2-$E2)/($H$1-$E$1))*(G$1-$E$1)+$E2 -> 11189.667 | H2: 11606 | I2: =(($M2-$H2)/($M$1-$H$1))*(I$1-$H$1)+$H2 -> 12190.2 | J2: =(($M2-$H2)/($M$1-$H$1))*(J$1-$H$1)+$H2 -> 12774.4 | K2: =(($M2-$H2)/($M$1-$H$1))*(K$1-$H$1)+$H2 -> 13358.6 | L2: =(($M2-$H2)/($M$1-$H$1))*(L$1-$H$1)+$H2 -> 13942.8 | M2: 14527 | N2: =(($R2-$M2)/($R$1-$M$1))*(N$1-$M$1)+$M2 -> 14518 | O2: =(($R2-$M2)/($R$1-$M$1))*(O$1-$M$1)+$M2 -> 14509 | P2: =(($R2-$M2)/($R$1-$M$1))*(P$1-$M$1)+$M2 -> 14500 | Q2: =(($R2-$M2)/($R$1-$M$1))*(Q$1-$M$1)+$M2 -> 14491 | R2: 14482 | S2: =(($W2-$R2)/($W$1-$R$1))*(S$1-$R$1)+$R2 -> 14420.4 | T2: =(($W2-$R2)/($W$1-$R$1))*(T$1-$R$1)+$R2 -> 14358.8 | U2: =(($W2-$R2)/($W$1-$R$1))*(U$1-$R$1)+$R2 -> 14297.2 | V2: =(($W2-$R2)/($W$1-$R$1))*(V$1-$R$1)+$R2 -> 14235.6 | W2: 14174 | X2: =(($AB2-$W2)/($AB$1-$W$1))*(X$1-$W$1)+$W2 -> 14327.8 | Y2: =(($AB2-$W2)/($AB$1-$W$1))*(Y$1-$W$1)+$W2 -> 14481.6 | Z2: =(($AB2-$W2)/($AB$1-$W$1))*(Z$1-$W$1)+$W2 -> 14635.4 | AA2: =(($AB2-$W2)/($AB$1-$W$1))*(AA$1-$W$1)+$W2 -> 14789.2 | AB2: 14943 | AC2: =(($AG2-$AB2)/($AG$1-$AB$1))*(AC$1-$AB$1)+$AB2 -> 14823 | AD2: =(($AG2-$AB2)/($AG$1-$AB$1))*(AD$1-$AB$1)+$AB2 -> 14703 | AE2: =(($AG2-$AB2)/($AG$1-$AB$1))*(AE$1-$AB$1)+$AB2 -> 14583 | AF2: =(($AG2-$AB2)/($AG$1-$AB$1))*(AF$1-$AB$1)+$AB2 -> 14463 | AG2: 14343 | AH2: =SUM(Tableau2[[#This Row],[2022]:[2050]]) -> 400797
A3: Electricity Networks | B3: Wire | C3: Aluminium | D3: APS | E3: 10357 | F3: =(($H3-$E3)/($H$1-$E$1))*(F$1-$E$1)+$E3 -> 10853.333 | G3: =(($H3-$E3)/($H$1-$E$1))*(G$1-$E$1)+$E3 -> 11349.667 | H3: 11846 | I3: =(($M3-$H3)/($M$1-$H$1))*(I$1-$H$1)+$H3 -> 12606.6 | J3: =(($M3-$H3)/($M$1-$H$1))*(J$1-$H$1)+$H3 -> 13367.2 | K3: =(($M3-$H3)/($M$1-$H$1))*(K$1-$H$1)+$H3 -> 14127.8 | L3: =(($M3-$H3)/($M$1-$H$1))*(L$1-$H$1)+$H3 -> 14888.4 | M3: 15649 | N3: =(($R3-$M3)/($R$1-$M$1))*(N$1-$M$1)+$M3 -> 15981.2 | O3: =(($R3-$M3)/($R$1-$M$1))*(O$1-$M$1)+$M3 -> 16313.4 | P3: =(($R3-$M3)/($R$1-$M$1))*(P$1-$M$1)+$M3 -> 16645.6 | Q3: =(($R3-$M3)/($R$1-$M$1))*(Q$1-$M$1)+$M3 -> 16977.8 | R3: 17310 | S3: =(($W3-$R3)/($W$1-$R$1))*(S$1-$R$1)+$R3 -> 17541.4 | T3: =(($W3-$R3)/($W$1-$R$1))*(T$1-$R$1)+$R3 -> 17772.8 | U3: =(($W3-$R3)/($W$1-$R$1))*(U$1-$R$1)+$R3 -> 18004.2 | V3: =(($W3-$R3)/($W$1-$R$1))*(V$1-$R$1)+$R3 -> 18235.6 | W3: 18467 | X3: =(($AB3-$W3)/($AB$1-$W$1))*(X$1-$W$1)+$W3 -> 18709.4 | Y3: =(($AB3-$W3)/($AB$1-$W$1))*(Y$1-$W$1)+$W3 -> 18951.8 | Z3: =(($AB3-$W3)/($AB$1-$W$1))*(Z$1-$W$1)+$W3 -> 19194.2 | AA3: =(($AB3-$W3)/($AB$1-$W$1))*(AA$1-$W$1)+$W3 -> 19436.6 | AB3: 19679 | AC3: =(($AG3-$AB3)/($AG$1-$AB$1))*(AC$1-$AB$1)+$AB3 -> 19534.6 | AD3: =(($AG3-$AB3)/($AG$1-$AB$1))*(AD$1-$AB$1)+$AB3 -> 19390.2 | AE3: =(($AG3-$AB3)/($AG$1-$AB$1))*(AE$1-$AB$1)+$AB3 -> 19245.8 | AF3: =(($AG3-$AB3)/($AG$1-$AB$1))*(AF$1-$AB$1)+$AB3 -> 19101.4 | AG3: 18957 | AH3: =SUM(Tableau2[[#This Row],[2022]:[2050]]) -> 480494
A4: Electricity Networks | B4: Wire | C4: Aluminium | D4: NZE | E4: 10357 | F4: =(($H4-$E4)/($H$1-$E$1))*(F$1-$E$1)+$E4 -> 11045.667 | G4: =(($H4-$E4)/($H$1-$E$1))*(G$1-$E$1)+$E4 -> 11734.333 | H4: 12423 | I4: =(($M4-$H4)/($M$1-$H$1))*(I$1-$H$1)+$H4 -> 13512.8 | J4: =(($M4-$H4)/($M$1-$H$1))*(J$1-$H$1)+$H4 -> 14602.6 | K4: =(($M4-$H4)/($M$1-$H$1))*(K$1-$H$1)+$H4 -> 15692.4 | L4: =(($M4-$H4)/($M$1-$H$1))*(L$1-$H$1)+$H4 -> 16782.2 | M4: 17872 | N4: =(($R4-$M4)/($R$1-$M$1))*(N$1-$M$1)+$M4 -> 18861.2 | O4: =(($R4-$M4)/($R$1-$M$1))*(O$1-$M$1)+$M4 -> 19850.4 | P4: =(($R4-$M4)/($R$1-$M$1))*(P$1-$M$1)+$M4 -> 20839.6 | Q4: =(($R4-$M4)/($R$1-$M$1))*(Q$1-$M$1)+$M4 -> 21828.8 | R4: 22818 | S4: =(($W4-$R4)/($W$1-$R$1))*(S$1-$R$1)+$R4 -> 23535 | T4: =(($W4-$R4)/($W$1-$R$1))*(T$1-$R$1)+$R4 -> 24252 | U4: =(($W4-$R4)/($W$1-$R$1))*(U$1-$R$1)+$R4 -> 24969 | V4: =(($W4-$R4)/($W$1-$R$1))*(V$1-$R$1)+$R4 -> 25686 | W4: 26403 | X4: =(($AB4-$W4)/($AB$1-$W$1))*(X$1-$W$1)+$W4 -> 26152 | Y4: =(($AB4-$W4)/($AB$1-$W$1))*(Y$1-$W$1)+$W4 -> 25901 | Z4: =(($AB4-$W4)/($AB$1-$W$1))*(Z$1-$W$1)+$W4 -> 25650 | AA4: =(($AB4-$W4)/($AB$1-$W$1))*(AA$1-$W$1)+$W4 -> 25399 | AB4: 25148 | AC4: =(($AG4-$AB4)/($AG$1-$AB$1))*(AC$1-$AB$1)+$AB4 -> 24270.2 | AD4: =(($AG4-$AB4)/($AG$1-$AB$1))*(AD$1-$AB$1)+$AB4 -> 23392.4 | AE4: =(($AG4-$AB4)/($AG$1-$AB$1))*(AE$1-$AB$1)+$AB4 -> 22514.6 | AF4: =(($AG4-$AB4)/($AG$1-$AB$1))*(AF$1-$AB$1)+$AB4 -> 21636.8 | AG4: 20759 | AH4: =SUM(Tableau2[[#This Row],[2022]:[2050]]) -> 593888
A5: Solar PV | B5: GaAs | C5: Arsenic | D5: SPS | E5: 0 | F5: =(($H5-$E5)/($H$1-$E$1))*(F$1-$E$1)+$E5 -> 0 | G5: =(($H5-$E5)/($H$1-$E$1))*(G$1-$E$1)+$E5 -> 0 | H5: 0 | I5: =(($M5-$H5)/($M$1-$H$1))*(I$1-$H$1)+$H5 -> 0.0380658 | J5: =(($M5-$H5)/($M$1-$H$1))*(J$1-$H$1)+$H5 -> 0.0761316 | K5: =(($M5-$H5)/($M$1-$H$1))*(K$1-$H$1)+$H5 -> 0.1141974 | L5: =(($M5-$H5)/($M$1-$H$1))*(L$1-$H$1)+$H5 -> 0.1522632 | M5: 0.190329 | N5: =(($R5-$M5)/($R$1-$M$1))*(N$1-$M$1)+$M5 -> 0.3692292 | O5: =(($R5-$M5)/($R$1-$M$1))*(O$1-$M$1)+$M5 -> 0.5481294 | P5: =(($R5-$M5)/($R$1-$M$1))*(P$1-$M$1)+$M5 -> 0.7270296 | Q5: =(($R5-$M5)/($R$1-$M$1))*(Q$1-$M$1)+$M5 -> 0.9059298 | R5: 1.08483 | S5: =(($W5-$R5)/($W$1-$R$1))*(S$1-$R$1)+$R5 -> 2.144222 | T5: =(($W5-$R5)/($W$1-$R$1))*(T$1-$R$1)+$R5 -> 3.203614 | U5: =(($W5-$R5)/($W$1-$R$1))*(U$1-$R$1)+$R5 -> 4.263006 | V5: =(($W5-$R5)/($W$1-$R$1))*(V$1-$R$1)+$R5 -> 5.322398 | W5: 6.38179 | X5: =(($AB5-$W5)/($AB$1-$W$1))*(X$1-$W$1)+$W5 -> 6.582482 | Y5: =(($AB5-$W5)/($AB$1-$W$1))*(Y$1-$W$1)+$W5 -> 6.783174 | Z5: =(($AB5-$W5)/($AB$1-$W$1))*(Z$1-$W$1)+$W5 -> 6.983866 | AA5: =(($AB5-$W5)/($AB$1-$W$1))*(AA$1-$W$1)+$W5 -> 7.184558 | AB5: 7.38525 | AC5: =(($AG5-$AB5)/($AG$1-$AB$1))*(AC$1-$AB$1)+$AB5 -> 7.578166 | AD5: =(($AG5-$AB5)/($AG$1-$AB$1))*(AD$1-$AB$1)+$AB5 -> 7.771082 | AE5: =(($AG5-$AB5)/($AG$1-$AB$1))*(AE$1-$AB$1)+$AB5 -> 7.963998 | AF5: =(($AG5-$AB5)/($AG$1-$AB$1))*(AF$1-$AB$1)+$AB5 -> 8.156914 | AG5: 8.34983 | AH5: =SUM(Tableau2[[#This Row],[2022]:[2050]]) -> 100.26049
A6: Solar PV | B6: GaAs | C6: Arsenic | D6: APS | E6: 0 | F6: =(($H6-$E6)/($H$1-$E$1))*(F$1-$E$1)+$E6 -> 0 | G6: =(($H6-$E6)/($H$1-$E$1))*(G$1-$E$1)+$E6 -> 0 | H6: 0 | I6: =(($M6-$H6)/($M$1-$H$1))*(I$1-$H$1)+$H6 -> 0.050845 | J6: =(($M6-$H6)/($M$1-$H$1))*(J$1-$H$1)+$H6 -> 0.10169 | K6: =(($M6-$H6)/($M$1-$H$1))*(K$1-$H$1)+$H6 -> 0.152535 | L6: =(($M6-$H6)/($M$1-$H$1))*(L$1-$H$1)+$H6 -> 0.20338 | M6: 0.254225 | N6: =(($R6-$M6)/($R$1-$M$1))*(N$1-$M$1)+$M6 -> 0.538666 | O6: =(($R6-$M6)/($R$1-$M$1))*(O$1-$M$1)+$M6 -> 0.823107 | P6: =(($R6-$M6)/($R$1-$M$1))*(P$1-$M$1)+$M6 -> 1.107548 | Q6: =(($R6-$M6)/($R$1-$M$1))*(Q$1-$M$1)+$M6 -> 1.391989 | R6: 1.67643 | S6: =(($W6-$R6)/($W$1-$R$1))*(S$1-$R$1)+$R6 -> 3.284686 | T6: =(($W6-$R6)/($W$1-$R$1))*(T$1-$R$1)+$R6 -> 4.892942 | U6: =(($W6-$R6)/($W$1-$R$1))*(U$1-$R$1)+$R6 -> 6.501198 | V6: =(($W6-$R6)/($W$1-$R$1))*(V$1-$R$1)+$R6 -> 8.109454 | W6: 9.71771 | X6: =(($AB6-$W6)/($AB$1-$W$1))*(X$1-$W$1)+$W6 -> 10.055748 | Y6: =(($AB6-$W6)/($AB$1-$W$1))*(Y$1-$W$1)+$W6 -> 10.393786 | Z6: =(($AB6-$W6)/($AB$1-$W$1))*(Z$1-$W$1)+$W6 -> 10.731824 | AA6: =(($AB6-$W6)/($AB$1-$W$1))*(AA$1-$W$1)+$W6 -> 11.069862 | AB6: 11.4079 | AC6: =(($AG6-$AB6)/($AG$1-$AB$1))*(AC$1-$AB$1)+$AB6 -> 11.69186 | AD6: =(($AG6-$AB6)/($AG$1-$AB$1))*(AD$1-$AB$1)+$AB6 -> 11.97582 | AE6: =(($AG6-$AB6)/($AG$1-$AB$1))*(AE$1-$AB$1)+$AB6 -> 12.25978 | AF6: =(($AG6-$AB6)/($AG$1-$AB$1))*(AF$1-$AB$1)+$AB6 -> 12.54374 | AG6: 12.8277 | AH6: =SUM(Tableau2[[#This Row],[2022]:[2050]]) -> 153.76443
A7: Solar PV | B7: GaAs | C7: Arsenic | D7: NZE | E7: 0 | F7: =(($H7-$E7)/($H$1-$E$1))*(F$1-$E$1)+$E7 -> 0 | G7: =(($H7-$E7)/($H$1-$E$1))*(G$1-$E$1)+$E7 -> 0 | H7: 0 | I7: =(($M7-$H7)/($M$1-$H$1))*(I$1-$H$1)+$H7 -> 0.0872272 | J7: =(($M7-$H7)/($M$1-$H$1))*(J$1-$H$1)+$H7 -> 0.1744544 | K7: =(($M7-$H7)/($M$1-$H$1))*(K$1-$H$1)+$H7 -> 0.2616816 | L7: =(($M7-$H7)/($M$1-$H$1))*(L$1-$H$1)+$H7 -> 0.3489088 | M7: 0.436136 | N7: =(($R7-$M7)/($R$1-$M$1))*(N$1-$M$1)+$M7 -> 0.8501088 | O7: =(($R7-$M7)/($R$1-$M$1))*(O$1-$M$1)+$M7 -> 1.2640816 | P7: =(($R7-$M7)/($R$1-$M$1))*(P$1-$M$1)+$M7 -> 1.6780544 | Q7: =(($R7-$M7)/($R$1-$M$1))*(Q$1-$M$1)+$M7 -> 2.0920272 | R7: 2.506 | S7: =(($W7-$R7)/($W$1-$R$1))*(S$1-$R$1)+$R7 -> 4.76706 | T7: =(($W7-$R7)/($W$1-$R$1))*(T$1-$R$1)+$R7 -> 7.02812 | U7: =(($W7-$R7)/($W$1-$R$1))*(U$1-$R$1)+$R7 -> 9.28918 | V7: =(($W7-$R7)/($W$1-$R$1))*(V$1-$R$1)+$R7 -> 11.55024 | W7: 13.8113 | X7: =(($AB7-$W7)/($AB$1-$W$1))*(X$1-$W$1)+$W7 -> 13.29246 | Y7: =(($AB7-$W7)/($AB$1-$W$1))*(Y$1-$W$1)+$W7 -> 12.77362 | Z7: =(($AB7-$W7)/($AB$1-$W$1))*(Z$1-$W$1)+$W7 -> 12.25478 | AA7: =(($AB7-$W7)/($AB$1-$W$1))*(AA$1-$W$1)+$W7 -> 11.73594 | AB7: 11.2171 | AC7: =(($AG7-$AB7)/($AG$1-$AB$1))*(AC$1-$AB$1)+$AB7 -> 11.48254 | AD7: =(($AG7-$AB7)/($AG$1-$AB$1))*(AD$1-$AB$1)+$AB7 -> 11.74798 | AE7: =(($AG7-$AB7)/($AG$1-$AB$1))*(AE$1-$AB$1)+$AB7 -> 12.01342 | AF7: =(($AG7-$AB7)/($AG$1-$AB$1))*(AF$1-$AB$1)+$AB7 -> 12.27886 | AG7: 12.5443 | AH7: =SUM(Tableau2[[#This Row],[2022]:[2050]]) -> 177.48558
A8: Wind | B8: PMSG | C8: Boron | D8: SPS | E8: 0.158457 | F8: =(($H8-$E8)/($H$1-$E$1))*(F$1-$E$1)+$E8 -> 0.16416867 | G8: =(($H8-$E8)/($H$1-$E$1))*(G$1-$E$1)+$E8 -> 0.16988033 | H8: 0.175592 | I8: =(($M8-$H8)/($M$1-$H$1))*(I$1-$H$1)+$H8 -> 0.2034132 | J8: =(($M8-$H8)/($M$1-$H$1))*(J$1-$H$1)+$H8 -> 0.2312344 | K8: =(($M8-$H8)/($M$1-$H$1))*(K$1-$H$1)+$H8 -> 0.2590556 | L8: =(($M8-$H8)/($M$1-$H$1))*(L$1-$H$1)+$H8 -> 0.2868768 | M8: 0.314698 | N8: =(($R8-$M8)/($R$1-$M$1))*(N$1-$M$1)+$M8 -> 0.309271 | O8: =(($R8-$M8)/($R$1-$M$1))*(O$1-$M$1)+$M8 -> 0.303844 | P8: =(($R8-$M8)/($R$1-$M$1))*(P$1-$M$1)+$M8 -> 0.298417 | Q8: =(($R8-$M8)/($R$1-$M$1))*(Q$1-$M$1)+$M8 -> 0.29299 | R8: 0.287563 | S8: =(($W8-$R8)/($W$1-$R$1))*(S$1-$R$1)+$R8 -> 0.2819488 | T8: =(($W8-$R8)/($W$1-$R$1))*(T$1-$R$1)+$R8 -> 0.2763346 | U8: =(($W8-$R8)/($W$1-$R$1))*(U$1-$R$1)+$R8 -> 0.2707204 | V8: =(($W8-$R8)/($W$1-$R$1))*(V$1-$R$1)+$R8 -> 0.2651062 | W8: 0.259492 | X8: =(($AB8-$W8)/($AB$1-$W$1))*(X$1-$W$1)+$W8 -> 0.2734476 | Y8: =(($AB8-$W8)/($AB$1-$W$1))*(Y$1-$W$1)+$W8 -> 0.2874032 | Z8: =(($AB8-$W8)/($AB$1-$W$1))*(Z$1-$W$1)+$W8 -> 0.3013588 | AA8: =(($AB8-$W8)/($AB$1-$W$1))*(AA$1-$W$1)+$W8 -> 0.3153144 | AB8: 0.32927 | AC8: =(($AG8-$AB8)/($AG$1-$AB$1))*(AC$1-$AB$1)+$AB8 -> 0.3449992 | AD8: =(($AG8-$AB8)/($AG$1-$AB$1))*(AD$1-$AB$1)+$AB8 -> 0.3607284 | AE8: =(($AG8-$AB8)/($AG$1-$AB$1))*(AE$1-$AB$1)+$AB8 -> 0.3764576 | AF8: =(($AG8-$AB8)/($AG$1-$AB$1))*(AF$1-$AB$1)+$AB8 -> 0.3921868 | AG8: 0.407916 | AH8: =SUM(Tableau2[[#This Row],[2022]:[2050]]) -> 8.198145
A9: Wind | B9: PMSG | C9: Boron | D9: APS | E9: 0.158457 | F9: =(($H9-$E9)/($H$1-$E$1))*(F$1-$E$1)+$E9 -> 0.180978 | G9: =(($H9-$E9)/($H$1-$E$1))*(G$1-$E$1)+$E9 -> 0.203499 | H9: 0.22602 | I9: =(($M9-$H9)/($M$1-$H$1))*(I$1-$H$1)+$H9 -> 0.2627336 | J9: =(($M9-$H9)/($M$1-$H$1))*(J$1-$H$1)+$H9 -> 0.2994472 | K9: =(($M9-$H9)/($M$1-$H$1))*(K$1-$H$1)+$H9 -> 0.3361608 | L9: =(($M9-$H9)/($M$1-$H$1))*(L$1-$H$1)+$H9 -> 0.3728744 | M9: 0.409588 | N9: =(($R9-$M9)/($R$1-$M$1))*(N$1-$M$1)+$M9 -> 0.4227988 | O9: =(($R9-$M9)/($R$1-$M$1))*(O$1-$M$1)+$M9 -> 0.4360096 | P9: =(($R9-$M9)/($R$1-$M$1))*(P$1-$M$1)+$M9 -> 0.4492204 | Q9: =(($R9-$M9)/($R$1-$M$1))*(Q$1-$M$1)+$M9 -> 0.4624312 | R9: 0.475642 | S9: =(($W9-$R9)/($W$1-$R$1))*(S$1-$R$1)+$R9 -> 0.479363 | T9: =(($W9-$R9)/($W$1-$R$1))*(T$1-$R$1)+$R9 -> 0.483084 | U9: =(($W9-$R9)/($W$1-$R$1))*(U$1-$R$1)+$R9 -> 0.486805 | V9: =(($W9-$R9)/($W$1-$R$1))*(V$1-$R$1)+$R9 -> 0.490526 | W9: 0.494247 | X9: =(($AB9-$W9)/($AB$1-$W$1))*(X$1-$W$1)+$W9 -> 0.5036634 | Y9: =(($AB9-$W9)/($AB$1-$W$1))*(Y$1-$W$1)+$W9 -> 0.5130798 | Z9: =(($AB9-$W9)/($AB$1-$W$1))*(Z$1-$W$1)+$W9 -> 0.5224962 | AA9: =(($AB9-$W9)/($AB$1-$W$1))*(AA$1-$W$1)+$W9 -> 0.5319126 | AB9: 0.541329 | AC9: =(($AG9-$AB9)/($AG$1-$AB$1))*(AC$1-$AB$1)+$AB9 -> 0.5616816 | AD9: =(($AG9-$AB9)/($AG$1-$AB$1))*(AD$1-$AB$1)+$AB9 -> 0.5820342 | AE9: =(($AG9-$AB9)/($AG$1-$AB$1))*(AE$1-$AB$1)+$AB9 -> 0.6023868 | AF9: =(($AG9-$AB9)/($AG$1-$AB$1))*(AF$1-$AB$1)+$AB9 -> 0.6227394 | AG9: 0.643092 | AH9: =SUM(Tableau2[[#This Row],[2022]:[2050]]) -> 12.7543
A10: Wind | B10: PMSG | C10: Boron | D10: NZE | E10: 0.158457 | F10: =(($H10-$E10)/($H$1-$E$1))*(F$1-$E$1)+$E10 -> 0.19965233 | G10: =(($H10-$E10)/($H$1-$E$1))*(G$1-$E$1)+$E10 -> 0.24084767 | H10: 0.282043 | I10: =(($M10-$H10)/($M$1-$H$1))*(I$1-$H$1)+$H10 -> 0.3717512 | J10: =(($M10-$H10)/($M$1-$H$1))*(J$1-$H$1)+$H10 -> 0.4614594 | K10: =(($M10-$H10)/($M$1-$H$1))*(K$1-$H$1)+$H10 -> 0.5511676 | L10: =(($M10-$H10)/($M$1-$H$1))*(L$1-$H$1)+$H10 -> 0.6408758 | M10: 0.730584 | N10: =(($R10-$M10)/($R$1-$M$1))*(N$1-$M$1)+$M10 -> 0.7300572 | O10: =(($R10-$M10)/($R$1-$M$1))*(O$1-$M$1)+$M10 -> 0.7295304 | P10: =(($R10-$M10)/($R$1-$M$1))*(P$1-$M$1)+$M10 -> 0.7290036 | Q10: =(($R10-$M10)/($R$1-$M$1))*(Q$1-$M$1)+$M10 -> 0.7284768 | R10: 0.72795 | S10: =(($W10-$R10)/($W$1-$R$1))*(S$1-$R$1)+$R10 -> 0.7205764 | T10: =(($W10-$R10)/($W$1-$R$1))*(T$1-$R$1)+$R10 -> 0.7132028 | U10: =(($W10-$R10)/($W$1-$R$1))*(U$1-$R$1)+$R10 -> 0.7058292 | V10: =(($W10-$R10)/($W$1-$R$1))*(V$1-$R$1)+$R10 -> 0.6984556 | W10: 0.691082 | X10: =(($AB10-$W10)/($AB$1-$W$1))*(X$1-$W$1)+$W10 -> 0.6473418 | Y10: =(($AB10-$W10)/($AB$1-$W$1))*(Y$1-$W$1)+$W10 -> 0.6036016 | Z10: =(($AB10-$W10)/($AB$1-$W$1))*(Z$1-$W$1)+$W10 -> 0.5598614 | AA10: =(($AB10-$W10)/($AB$1-$W$1))*(AA$1-$W$1)+$W10 -> 0.5161212 | AB10: 0.472381 | AC10: =(($AG10-$AB10)/($AG$1-$AB$1))*(AC$1-$AB$1)+$AB10 -> 0.5270274 | AD10: =(($AG10-$AB10)/($AG$1-$AB$1))*(AD$1-$AB$1)+$AB10 -> 0.5816738 | AE10: =(($AG10-$AB10)/($AG$1-$AB$1))*(AE$1-$AB$1)+$AB10 -> 0.6363202 | AF10: =(($AG10-$AB10)/($AG$1-$AB$1))*(AF$1-$AB$1)+$AB10 -> 0.6909666 | AG10: 0.745613 | AH10: =SUM(Tableau2[[#This Row],[2022]:[2050]]) -> 16.79191
A11: Solar PV | B11: CdTe | C11: Cadmium | D11: SPS | E11: 0.406292 | F11: =(($H11-$E11)/($H$1-$E$1))*(F$1-$E$1)+$E11 -> 0.40829833 | G11: =(($H11-$E11)/($H$1-$E$1))*(G$1-$E$1)+$E11 -> 0.41030467 | H11: 0.412311 | I11: =(($M11-$H11)/($M$1-$H$1))*(I$1-$H$1)+$H11 -> 0.4040802 | J11: =(($M11-$H11)/($M$1-$H$1))*(J$1-$H$1)+$H11 -> 0.3958494 | K11: =(($M11-$H11)/($M$1-$H$1))*(K$1-$H$1)+$H11 -> 0.3876186 | L11: =(($M11-$H11)/($M$1-$H$1))*(L$1-$H$1)+$H11 -> 0.3793878 | M11: 0.371157 | N11: =(($R11-$M11)/($R$1-$M$1))*(N$1-$M$1)+$M11 -> 0.3726554 | O11: =(($R11-$M11)/($R$1-$M$1))*(O$1-$M$1)+$M11 -> 0.3741538 | P11: =(($R11-$M11)/($R$1-$M$1))*(P$1-$M$1)+$M11 -> 0.3756522 | Q11: =(($R11-$M11)/($R$1-$M$1))*(Q$1-$M$1)+$M11 -> 0.3771506 | R11: 0.378649 | S11: =(($W11-$R11)/($W$1-$R$1))*(S$1-$R$1)+$R11 -> 0.3829292 | T11: =(($W11-$R11)/($W$1-$R$1))*(T$1-$R$1)+$R11 -> 0.3872094 | U11: =(($W11-$R11)/($W$1-$R$1))*(U$1-$R$1)+$R11 -> 0.3914896 | V11: =(($W11-$R11)/($W$1-$R$1))*(V$1-$R$1)+$R11 -> 0.3957698 | W11: 0.40005 | X11: =(($AB11-$W11)/($AB$1-$W$1))*(X$1-$W$1)+$W11 -> 0.4095288 | Y11: =(($AB11-$W11)/($AB$1-$W$1))*(Y$1-$W$1)+$W11 -> 0.4190076 | Z11: =(($AB11-$W11)/($AB$1-$W$1))*(Z$1-$W$1)+$W11 -> 0.4284864 | AA11: =(($AB11-$W11)/($AB$1-$W$1))*(AA$1-$W$1)+$W11 -> 0.4379652 | AB11: 0.447444 | AC11: =(($AG11-$AB11)/($AG$1-$AB$1))*(AC$1-$AB$1)+$AB11 -> 0.4559458 | AD11: =(($AG11-$AB11)/($AG$1-$AB$1))*(AD$1-$AB$1)+$AB11 -> 0.4644476 | AE11: =(($AG11-$AB11)/($AG$1-$AB$1))*(AE$1-$AB$1)+$AB11 -> 0.4729494 | AF11: =(($AG11-$AB11)/($AG$1-$AB$1))*(AF$1-$AB$1)+$AB11 -> 0.4814512 | AG11: 0.489953 | AH11: =SUM(Tableau2[[#This Row],[2022]:[2050]]) -> 11.918187
A12: Solar PV | B12: CdTe | C12: Cadmium | D12: APS | E12: 0.406292 | F12: =(($H12-$E12)/($H$1-$E$1))*(F$1-$E$1)+$E12 -> 0.43390633 | G12: =(($H12-$E12)/($H$1-$E$1))*(G$1-$E$1)+$E12 -> 0.46152067 | H12: 0.489135 | I12: =(($M12-$H12)/($M$1-$H$1))*(I$1-$H$1)+$H12 -> 0.4878322 | J12: =(($M12-$H12)/($M$1-$H$1))*(J$1-$H$1)+$H12 -> 0.4865294 | K12: =(($M12-$H12)/($M$1-$H$1))*(K$1-$H$1)+$H12 -> 0.4852266 | L12: =(($M12-$H12)/($M$1-$H$1))*(L$1-$H$1)+$H12 -> 0.4839238 | M12: 0.482621 | N12: =(($R12-$M12)/($R$1-$M$1))*(N$1-$M$1)+$M12 -> 0.4956736 | O12: =(($R12-$M12)/($R$1-$M$1))*(O$1-$M$1)+$M12 -> 0.5087262 | P12: =(($R12-$M12)/($R$1-$M$1))*(P$1-$M$1)+$M12 -> 0.5217788 | Q12: =(($R12-$M12)/($R$1-$M$1))*(Q$1-$M$1)+$M12 -> 0.5348314 | R12: 0.547884 | S12: =(($W12-$R12)/($W$1-$R$1))*(S$1-$R$1)+$R12 -> 0.546293 | T12: =(($W12-$R12)/($W$1-$R$1))*(T$1-$R$1)+$R12 -> 0.544702 | U12: =(($W12-$R12)/($W$1-$R$1))*(U$1-$R$1)+$R12 -> 0.543111 | V12: =(($W12-$R12)/($W$1-$R$1))*(V$1-$R$1)+$R12 -> 0.54152 | W12: 0.539929 | X12: =(($AB12-$W12)/($AB$1-$W$1))*(X$1-$W$1)+$W12 -> 0.5474646 | Y12: =(($AB12-$W12)/($AB$1-$W$1))*(Y$1-$W$1)+$W12 -> 0.5550002 | Z12: =(($AB12-$W12)/($AB$1-$W$1))*(Z$1-$W$1)+$W12 -> 0.5625358 | AA12: =(($AB12-$W12)/($AB$1-$W$1))*(AA$1-$W$1)+$W12 -> 0.5700714 | AB12: 0.577607 | AC12: =(($AG12-$AB12)/($AG$1-$AB$1))*(AC$1-$AB$1)+$AB12 -> 0.576473 | AD12: =(($AG12-$AB12)/($AG$1-$AB$1))*(AD$1-$AB$1)+$AB12 -> 0.575339 | AE12: =(($AG12-$AB12)/($AG$1-$AB$1))*(AE$1-$AB$1)+$AB12 -> 0.574205 | AF12: =(($AG12-$AB12)/($AG$1-$AB$1))*(AF$1-$AB$1)+$AB12 -> 0.573071 | AG12: 0.571937 | AH12: =SUM(Tableau2[[#This Row],[2022]:[2050]]) -> 15.22514
A13: Solar PV | B13: CdTe | C13: Cadmium | D13: NZE | E13: 0.406292 | F13: =(($H13-$E13)/($H$1-$E$1))*(F$1-$E$1)+$E13 -> 0.52415567 | G13: =(($H13-$E13)/($H$1-$E$1))*(G$1-$E$1)+$E13 -> 0.64201933 | H13: 0.759883 | I13: =(($M13-$H13)/($M$1-$H$1))*(I$1-$H$1)+$H13 -> 0.8462964 | J13: =(($M13-$H13)/($M$1-$H$1))*(J$1-$H$1)+$H13 -> 0.9327098 | K13: =(($M13-$H13)/($M$1-$H$1))*(K$1-$H$1)+$H13 -> 1.0191232 | L13: =(($M13-$H13)/($M$1-$H$1))*(L$1-$H$1)+$H13 -> 1.1055366 | M13: 1.19195 | N13: =(($R13-$M13)/($R$1-$M$1))*(N$1-$M$1)+$M13 -> 1.173794 | O13: =(($R13-$M13)/($R$1-$M$1))*(O$1-$M$1)+$M13 -> 1.155638 | P13: =(($R13-$M13)/($R$1-$M$1))*(P$1-$M$1)+$M13 -> 1.137482 | Q13: =(($R13-$M13)/($R$1-$M$1))*(Q$1-$M$1)+$M13 -> 1.119326 | R13: 1.10117 | S13: =(($W13-$R13)/($W$1-$R$1))*(S$1-$R$1)+$R13 -> 1.067321 | T13: =(($W13-$R13)/($W$1-$R$1))*(T$1-$R$1)+$R13 -> 1.033472 | U13: =(($W13-$R13)/($W$1-$R$1))*(U$1-$R$1)+$R13 -> 0.999623 | V13: =(($W13-$R13)/($W$1-$R$1))*(V$1-$R$1)+$R13 -> 0.965774 | W13: 0.931925 | X13: =(($AB13-$W13)/($AB$1-$W$1))*(X$1-$W$1)+$W13 -> 0.861181 | Y13: =(($AB13-$W13)/($AB$1-$W$1))*(Y$1-$W$1)+$W13 -> 0.790437 | Z13: =(($AB13-$W13)/($AB$1-$W$1))*(Z$1-$W$1)+$W13 -> 0.719693 | AA13: =(($AB13-$W13)/($AB$1-$W$1))*(AA$1-$W$1)+$W13 -> 0.648949 | AB13: 0.578205 | AC13: =(($AG13-$AB13)/($AG$1-$AB$1))*(AC$1-$AB$1)+$AB13 -> 0.5448936 | AD13: =(($AG13-$AB13)/($AG$1-$AB$1))*(AD$1-$AB$1)+$AB13 -> 0.5115822 | AE13: =(($AG13-$AB13)/($AG$1-$AB$1))*(AE$1-$AB$1)+$AB13 -> 0.4782708 | AF13: =(($AG13-$AB13)/($AG$1-$AB$1))*(AF$1-$AB$1)+$AB13 -> 0.4449594 | AG13: 0.411648 | AH13: =SUM(Tableau2[[#This Row],[2022]:[2050]]) -> 24.10331
... A25: Battery Storage | B25: Battery | C25: Cobalt | D25: NZE | E25: 3.58853 | F25: =(($H25-$E25)/($H$1-$E$1))*(F$1-$E$1)+$E25 -> 4.4689033 | G25: =(($H25-$E25)/($H$1-$E$1))*(G$1-$E$1)+$E25 -> 5.3492767 | H25: 6.22965 | I25: =(($M25-$H25)/($M$1-$H$1))*(I$1-$H$1)+$H25 -> 8.38794 | J25: =(($M25-$H25)/($M$1-$H$1))*(J$1-$H$1)+$H25 -> 10.54623 | K25: =(($M25-$H25)/($M$1-$H$1))*(K$1-$H$1)+$H25 -> 12.70452 | L25: =(($M25-$H25)/($M$1-$H$1))*(L$1-$H$1)+$H25 -> 14.86281 | M25: 17.0211 | N25: =(($R25-$M25)/($R$1-$M$1))*(N$1-$M$1)+$M25 -> 17.16094 | O25: =(($R25-$M25)/($R$1-$M$1))*(O$1-$M$1)+$M25 -> 17.30078 | P25: =(($R25-$M25)/($R$1-$M$1))*(P$1-$M$1)+$M25 -> 17.44062 | Q25: =(($R25-$M25)/($R$1-$M$1))*(Q$1-$M$1)+$M25 -> 17.58046 | R25: 17.7203 | S25: =(($W25-$R25)/($W$1-$R$1))*(S$1-$R$1)+$R25 -> 17.06376 | T25: =(($W25-$R25)/($W$1-$R$1))*(T$1-$R$1)+$R25 -> 16.40722 | U25: =(($W25-$R25)/($W$1-$R$1))*(U$1-$R$1)+$R25 -> 15.75068 | V25: =(($W25-$R25)/($W$1-$R$1))*(V$1-$R$1)+$R25 -> 15.09414 | W25: 14.4376 | X25: =(($AB25-$W25)/($AB$1-$W$1))*(X$1-$W$1)+$W25 -> 12.940244 | Y25: =(($AB25-$W25)/($AB$1-$W$1))*(Y$1-$W$1)+$W25 -> 11.442888 | Z25: =(($AB25-$W25)/($AB$1-$W$1))*(Z$1-$W$1)+$W25 -> 9.945532 | AA25: =(($AB25-$W25)/($AB$1-$W$1))*(AA$1-$W$1)+$W25 -> 8.448176 | AB25: 6.95082 | AC25: =(($AG25-$AB25)/($AG$1-$AB$1))*(AC$1-$AB$1)+$AB25 -> 5.560656 | AD25: =(($AG25-$AB25)/($AG$1-$AB$1))*(AD$1-$AB$1)+$AB25 -> 4.170492 | AE25: =(($AG25-$AB25)/($AG$1-$AB$1))*(AE$1-$AB$1)+$AB25 -> 2.780328 | AF25: =(($AG25-$AB25)/($AG$1-$AB$1))*(AF$1-$AB$1)+$AB25 -> 1.390164 | AG25: 0 | AH25: =SUM(Tableau2[[#This Row],[2022]:[2050]]) -> 312.74476
A26: Hydrogen | C26: Cobalt | D26: SPS | E26: 0.0107346 | F26: =(($H26-$E26)/($H$1-$E$1))*(F$1-$E$1)+$E26 -> 0.010594967 | G26: =(($H26-$E26)/($H$1-$E$1))*(G$1-$E$1)+$E26 -> 0.010455333 | H26: 0.0103157 | I26: =(($M26-$H26)/($M$1-$H$1))*(I$1-$H$1)+$H26 -> 0.01103312 | J26: =(($M26-$H26)/($M$1-$H$1))*(J$1-$H$1)+$H26 -> 0.01175054 | K26: =(($M26-$H26)/($M$1-$H$1))*(K$1-$H$1)+$H26 -> 0.01246796 | L26: =(($M26-$H26)/($M$1-$H$1))*(L$1-$H$1)+$H26 -> 0.01318538 | M26: 0.0139028 | N26: =(($R26-$M26)/($R$1-$M$1))*(N$1-$M$1)+$M26 -> 0.012595864 | O26: =(($R26-$M26)/($R$1-$M$1))*(O$1-$M$1)+$M26 -> 0.011288928 | P26: =(($R26-$M26)/($R$1-$M$1))*(P$1-$M$1)+$M26 -> 0.009981992 | Q26: =(($R26-$M26)/($R$1-$M$1))*(Q$1-$M$1)+$M26 -> 0.008675056 | R26: 0.00736812 | S26: =(($W26-$R26)/($W$1-$R$1))*(S$1-$R$1)+$R26 -> 0.006554462 | T26: =(($W26-$R26)/($W$1-$R$1))*(T$1-$R$1)+$R26 -> 0.005740804 | U26: =(($W26-$R26)/($W$1-$R$1))*(U$1-$R$1)+$R26 -> 0.004927146 | V26: =(($W26-$R26)/($W$1-$R$1))*(V$1-$R$1)+$R26 -> 0.004113488 | W26: 0.00329983 | X26: =(($AB26-$W26)/($AB$1-$W$1))*(X$1-$W$1)+$W26 -> 0.003352192 | Y26: =(($AB26-$W26)/($AB$1-$W$1))*(Y$1-$W$1)+$W26 -> 0.003404554 | Z26: =(($AB26-$W26)/($AB$1-$W$1))*(Z$1-$W$1)+$W26 -> 0.003456916 | AA26: =(($AB26-$W26)/($AB$1-$W$1))*(AA$1-$W$1)+$W26 -> 0.003509278 | AB26: 0.00356164 | AC26: =(($AG26-$AB26)/($AG$1-$AB$1))*(AC$1-$AB$1)+$AB26 -> 0.003840044 | AD26: =(($AG26-$AB26)/($AG$1-$AB$1))*(AD$1-$AB$1)+$AB26 -> 0.004118448 | AE26: =(($AG26-$AB26)/($AG$1-$AB$1))*(AE$1-$AB$1)+$AB26 -> 0.004396852 | AF26: =(($AG26-$AB26)/($AG$1-$AB$1))*(AF$1-$AB$1)+$AB26 -> 0.004675256 | AG26: 0.00495366 | AH26: =SUM(Tableau2[[#This Row],[2022]:[2050]]) -> 0.21825493
A27: Hydrogen | C27: Cobalt | D27: APS | E27: 0.0107346 | F27: =(($H27-$E27)/($H$1-$E$1))*(F$1-$E$1)+$E27 -> 0.034218033 | G27: =(($H27-$E27)/($H$1-$E$1))*(G$1-$E$1)+$E27 -> 0.057701467 | H27: 0.0811849 | I27: =(($M27-$H27)/($M$1-$H$1))*(I$1-$H$1)+$H27 -> 0.08851232 | J27: =(($M27-$H27)/($M$1-$H$1))*(J$1-$H$1)+$H27 -> 0.09583974 | K27: =(($M27-$H27)/($M$1-$H$1))*(K$1-$H$1)+$H27 -> 0.10316716 | L27: =(($M27-$H27)/($M$1-$H$1))*(L$1-$H$1)+$H27 -> 0.11049458 | M27: 0.117822 | N27: =(($R27-$M27)/($R$1-$M$1))*(N$1-$M$1)+$M27 -> 0.109362 | O27: =(($R27-$M27)/($R$1-$M$1))*(O$1-$M$1)+$M27 -> 0.100902 | P27: =(($R27-$M27)/($R$1-$M$1))*(P$1-$M$1)+$M27 -> 0.092442 | Q27: =(($R27-$M27)/($R$1-$M$1))*(Q$1-$M$1)+$M27 -> 0.083982 | R27: 0.075522 | S27: =(($W27-$R27)/($W$1-$R$1))*(S$1-$R$1)+$R27 -> 0.0685072 | T27: =(($W27-$R27)/($W$1-$R$1))*(T$1-$R$1)+$R27 -> 0.0614924 | U27: =(($W27-$R27)/($W$1-$R$1))*(U$1-$R$1)+$R27 -> 0.0544776 | V27: =(($W27-$R27)/($W$1-$R$1))*(V$1-$R$1)+$R27 -> 0.0474628 | W27: 0.040448 | X27: =(($AB27-$W27)/($AB$1-$W$1))*(X$1-$W$1)+$W27 -> 0.04058222 | Y27: =(($AB27-$W27)/($AB$1-$W$1))*(Y$1-$W$1)+$W27 -> 0.04071644 | Z27: =(($AB27-$W27)/($AB$1-$W$1))*(Z$1-$W$1)+$W27 -> 0.04085066 | AA27: =(($AB27-$W27)/($AB$1-$W$1))*(AA$1-$W$1)+$W27 -> 0.04098488 | AB27: 0.0411191 | AC27: =(($AG27-$AB27)/($AG$1-$AB$1))*(AC$1-$AB$1)+$AB27 -> 0.04359012 | AD27: =(($AG27-$AB27)/($AG$1-$AB$1))*(AD$1-$AB$1)+$AB27 -> 0.04606114 | AE27: =(($AG27-$AB27)/($AG$1-$AB$1))*(AE$1-$AB$1)+$AB27 -> 0.04853216 | AF27: =(($AG27-$AB27)/($AG$1-$AB$1))*(AF$1-$AB$1)+$AB27 -> 0.05100318 | AG27: 0.0534742 | AH27: =SUM(Tableau2[[#This Row],[2022]:[2050]]) -> 1.8811869
A28: Hydrogen | C28: Cobalt | D28: NZE | E28: 0.0107346 | F28: =(($H28-$E28)/($H$1-$E$1))*(F$1-$E$1)+$E28 -> 0.0575234 | G28: =(($H28-$E28)/($H$1-$E$1))*(G$1-$E$1)+$E28 -> 0.1043122 | H28: 0.151101 | I28: =(($M28-$H28)/($M$1-$H$1))*(I$1-$H$1)+$H28 -> 0.1812942 | J28: =(($M28-$H28)/($M$1-$H$1))*(J$1-$H$1)+$H28 -> 0.2114874 | K28: =(($M28-$H28)/($M$1-$H$1))*(K$1-$H$1)+$H28 -> 0.2416806 | L28: =(($M28-$H28)/($M$1-$H$1))*(L$1-$H$1)+$H28 -> 0.2718738 | M28: 0.302067 | N28: =(($R28-$M28)/($R$1-$M$1))*(N$1-$M$1)+$M28 -> 0.2828426 | O28: =(($R28-$M28)/($R$1-$M$1))*(O$1-$M$1)+$M28 -> 0.2636182 | P28: =(($R28-$M28)/($R$1-$M$1))*(P$1-$M$1)+$M28 -> 0.2443938 | Q28: =(($R28-$M28)/($R$1-$M$1))*(Q$1-$M$1)+$M28 -> 0.2251694 | R28: 0.205945 | S28: =(($W28-$R28)/($W$1-$R$1))*(S$1-$R$1)+$R28 -> 0.18091438 | T28: =(($W28-$R28)/($W$1-$R$1))*(T$1-$R$1)+$R28 -> 0.15588376 | U28: =(($W28-$R28)/($W$1-$R$1))*(U$1-$R$1)+$R28 -> 0.13085314 | V28: =(($W28-$R28)/($W$1-$R$1))*(V$1-$R$1)+$R28 -> 0.10582252 | W28: 0.0807919 | X28: =(($AB28-$W28)/($AB$1-$W$1))*(X$1-$W$1)+$W28 -> 0.07571734 | Y28: =(($AB28-$W28)/($AB$1-$W$1))*(Y$1-$W$1)+$W28 -> 0.07064278 | Z28: =(($AB28-$W28)/($AB$1-$W$1))*(Z$1-$W$1)+$W28 -> 0.06556822 | AA28: =(($AB28-$W28)/($AB$1-$W$1))*(AA$1-$W$1)+$W28 -> 0.06049366 | AB28: 0.0554191 | AC28: =(($AG28-$AB28)/($AG$1-$AB$1))*(AC$1-$AB$1)+$AB28 -> 0.05950908 | AD28: =(($AG28-$AB28)/($AG$1-$AB$1))*(AD$1-$AB$1)+$AB28 -> 0.06359906 | AE28: =(($AG28-$AB28)/($AG$1-$AB$1))*(AE$1-$AB$1)+$AB28 -> 0.06768904 | AF28: =(($AG28-$AB28)/($AG$1-$AB$1))*(AF$1-$AB$1)+$AB28 -> 0.07177902 | AG28: 0.075869 | AH28: =SUM(Tableau2[[#This Row],[2022]:[2050]]) -> 4.0745952
A29: Battery Storage | B29: Battery | C29: Copper | D29: SPS | E29: 20.4468 | F29: =(($H29-$E29)/($H$1-$E$1))*(F$1-$E$1)+$E29 -> 26.445767 | G29: =(($H29-$E29)/($H$1-$E$1))*(G$1-$E$1)+$E29 -> 32.444733 | H29: 38.4437 | I29: =(($M29-$H29)/($M$1-$H$1))*(I$1-$H$1)+$H29 -> 47.30054 | J29: =(($M29-$H29)/($M$1-$H$1))*(J$1-$H$1)+$H29 -> 56.15738 | K29: =(($M29-$H29)/($M$1-$H$1))*(K$1-$H$1)+$H29 -> 65.01422 | L29: =(($M29-$H29)/($M$1-$H$1))*(L$1-$H$1)+$H29 -> 73.87106 | M29: 82.7279 | N29: =(($R29-$M29)/($R$1-$M$1))*(N$1-$M$1)+$M29 -> 96.89972 | O29: =(($R29-$M29)/($R$1-$M$1))*(O$1-$M$1)+$M29 -> 111.07154 | P29: =(($R29-$M29)/($R$1-$M$1))*(P$1-$M$1)+$M29 -> 125.24336 | Q29: =(($R29-$M29)/($R$1-$M$1))*(Q$1-$M$1)+$M29 -> 139.41518 | R29: 153.587 | S29: =(($W29-$R29)/($W$1-$R$1))*(S$1-$R$1)+$R29 -> 167.9202 | T29: =(($W29-$R29)/($W$1-$R$1))*(T$1-$R$1)+$R29 -> 182.2534 | U29: =(($W29-$R29)/($W$1-$R$1))*(U$1-$R$1)+$R29 -> 196.5866 | V29: =(($W29-$R29)/($W$1-$R$1))*(V$1-$R$1)+$R29 -> 210.9198 | W29: 225.253 | X29: =(($AB29-$W29)/($AB$1-$W$1))*(X$1-$W$1)+$W29 -> 227.8992 | Y29: =(($AB29-$W29)/($AB$1-$W$1))*(Y$1-$W$1)+$W29 -> 230.5454 | Z29: =(($AB29-$W29)/($AB$1-$W$1))*(Z$1-$W$1)+$W29 -> 233.1916 | AA29: =(($AB29-$W29)/($AB$1-$W$1))*(AA$1-$W$1)+$W29 -> 235.8378 | AB29: 238.484 | AC29: =(($AG29-$AB29)/($AG$1-$AB$1))*(AC$1-$AB$1)+$AB29 -> 234.732 | AD29: =(($AG29-$AB29)/($AG$1-$AB$1))*(AD$1-$AB$1)+$AB29 -> 230.98 | AE29: =(($AG29-$AB29)/($AG$1-$AB$1))*(AE$1-$AB$1)+$AB29 -> 227.228 | AF29: =(($AG29-$AB29)/($AG$1-$AB$1))*(AF$1-$AB$1)+$AB29 -> 223.476 | AG29: 219.724 | AH29: =SUM(Tableau2[[#This Row],[2022]:[2050]]) -> 4354.0999
A30: Electricity Networks | B30: Wire | C30: Copper | D30: NZE | E30: 4181.61 | F30: =(($H30-$E30)/($H$1-$E$1))*(F$1-$E$1)+$E30 -> 4462.4933 | G30: =(($H30-$E30)/($H$1-$E$1))*(G$1-$E$1)+$E30 -> 4743.3767 | H30: 5024.26 | I30: =(($M30-$H30)/($M$1-$H$1))*(I$1-$H$1)+$H30 -> 5804.128 | J30: =(($M30-$H30)/($M$1-$H$1))*(J$1-$H$1)+$H30 -> 6583.996 | K30: =(($M30-$H30)/($M$1-$H$1))*(K$1-$H$1)+$H30 -> 7363.864 | L30: =(($M30-$H30)/($M$1-$H$1))*(L$1-$H$1)+$H30 -> 8143.732 | M30: 8923.6 | N30: =(($R30-$M30)/($R$1-$M$1))*(N$1-$M$1)+$M30 -> 9427.78 | O30: =(($R30-$M30)/($R$1-$M$1))*(O$1-$M$1)+$M30 -> 9931.96 | P30: =(($R30-$M30)/($R$1-$M$1))*(P$1-$M$1)+$M30 -> 10436.14 | Q30: =(($R30-$M30)/($R$1-$M$1))*(Q$1-$M$1)+$M30 -> 10940.32 | R30: 11444.5 | S30: =(($W30-$R30)/($W$1-$R$1))*(S$1-$R$1)+$R30 -> 11670.48 | T30: =(($W30-$R30)/($W$1-$R$1))*(T$1-$R$1)+$R30 -> 11896.46 | U30: =(($W30-$R30)/($W$1-$R$1))*(U$1-$R$1)+$R30 -> 12122.44 | V30: =(($W30-$R30)/($W$1-$R$1))*(V$1-$R$1)+$R30 -> 12348.42 | W30: 12574.4 | X30: =(($AB30-$W30)/($AB$1-$W$1))*(X$1-$W$1)+$W30 -> 12410.9 | Y30: =(($AB30-$W30)/($AB$1-$W$1))*(Y$1-$W$1)+$W30 -> 12247.4 | Z30: =(($AB30-$W30)/($AB$1-$W$1))*(Z$1-$W$1)+$W30 -> 12083.9 | AA30: =(($AB30-$W30)/($AB$1-$W$1))*(AA$1-$W$1)+$W30 -> 11920.4 | AB30: 11756.9 | AC30: =(($AG30-$AB30)/($AG$1-$AB$1))*(AC$1-$AB$1)+$AB30 -> 11361.088 | AD30: =(($AG30-$AB30)/($AG$1-$AB$1))*(AD$1-$AB$1)+$AB30 -> 10965.276 | AE30: =(($AG30-$AB30)/($AG$1-$AB$1))*(AE$1-$AB$1)+$AB30 -> 10569.464 | AF30: =(($AG30-$AB30)/($AG$1-$AB$1))*(AF$1-$AB$1)+$AB30 -> 10173.652 | AG30: 9777.84 | AH30: =SUM(Tableau2[[#This Row],[2022]:[2050]]) -> 281290.78
A31: Battery Storage | B31: Battery | C31: Copper | D31: APS | E31: 20.4468 | F31: =(($H31-$E31)/($H$1-$E$1))*(F$1-$E$1)+$E31 -> 31.0172 | G31: =(($H31-$E31)/($H$1-$E$1))*(G$1-$E$1)+$E31 -> 41.5876 | H31: 52.158 | I31: =(($M31-$H31)/($M$1-$H$1))*(I$1-$H$1)+$H31 -> 67.639 | J31: =(($M31-$H31)/($M$1-$H$1))*(J$1-$H$1)+$H31 -> 83.12 | K31: =(($M31-$H31)/($M$1-$H$1))*(K$1-$H$1)+$H31 -> 98.601 | L31: =(($M31-$H31)/($M$1-$H$1))*(L$1-$H$1)+$H31 -> 114.082 | M31: 129.563 | N31: =(($R31-$M31)/($R$1-$M$1))*(N$1-$M$1)+$M31 -> 149.7174 | O31: =(($R31-$M31)/($R$1-$M$1))*(O$1-$M$1)+$M31 -> 169.8718 | P31: =(($R31-$M31)/($R$1-$M$1))*(P$1-$M$1)+$M31 -> 190.0262 | Q31: =(($R31-$M31)/($R$1-$M$1))*(Q$1-$M$1)+$M31 -> 210.1806 | R31: 230.335 | S31: =(($W31-$R31)/($W$1-$R$1))*(S$1-$R$1)+$R31 -> 259.3982 | T31: =(($W31-$R31)/($W$1-$R$1))*(T$1-$R$1)+$R31 -> 288.4614 | U31: =(($W31-$R31)/($W$1-$R$1))*(U$1-$R$1)+$R31 -> 317.5246 | V31: =(($W31-$R31)/($W$1-$R$1))*(V$1-$R$1)+$R31 -> 346.5878 | W31: 375.651 | X31: =(($AB31-$W31)/($AB$1-$W$1))*(X$1-$W$1)+$W31 -> 383.0396 | Y31: =(($AB31-$W31)/($AB$1-$W$1))*(Y$1-$W$1)+$W31 -> 390.4282 | Z31: =(($AB31-$W31)/($AB$1-$W$1))*(Z$1-$W$1)+$W31 -> 397.8168 | AA31: =(($AB31-$W31)/($AB$1-$W$1))*(AA$1-$W$1)+$W31 -> 405.2054 | AB31: 412.594 | AC31: =(($AG31-$AB31)/($AG$1-$AB$1))*(AC$1-$AB$1)+$AB31 -> 418.8362 | AD31: =(($AG31-$AB31)/($AG$1-$AB$1))*(AD$1-$AB$1)+$AB31 -> 425.0784 | AE31: =(($AG31-$AB31)/($AG$1-$AB$1))*(AE$1-$AB$1)+$AB31 -> 431.3206 | AF31: =(($AG31-$AB31)/($AG$1-$AB$1))*(AF$1-$AB$1)+$AB31 -> 437.5628 | AG31: 443.805 | AH31: =SUM(Tableau2[[#This Row],[2022]:[2050]]) -> 7321.6556
A32: Electricity Networks | B32: Wire | C32: Copper | D32: APS | E32: 4181.61 | F32: =(($H32-$E32)/($H$1-$E$1))*(F$1-$E$1)+$E32 -> 4436.1633 | G32: =(($H32-$E32)/($H$1-$E$1))*(G$1-$E$1)+$E32 -> 4690.7167 | H32: 4945.27 | I32: =(($M32-$H32)/($M$1-$H$1))*(I$1-$H$1)+$H32 -> 5444.208 | J32: =(($M32-$H32)/($M$1-$H$1))*(J$1-$H$1)+$H32 -> 5943.146 | K32: =(($M32-$H32)/($M$1-$H$1))*(K$1-$H$1)+$H32 -> 6442.084 | L32: =(($M32-$H32)/($M$1-$H$1))*(L$1-$H$1)+$H32 -> 6941.022 | M32: 7439.96 | N32: =(($R32-$M32)/($R$1-$M$1))*(N$1-$M$1)+$M32 -> 7630.848 | O32: =(($R32-$M32)/($R$1-$M$1))*(O$1-$M$1)+$M32 -> 7821.736 | P32: =(($R32-$M32)/($R$1-$M$1))*(P$1-$M$1)+$M32 -> 8012.624 | Q32: =(($R32-$M32)/($R$1-$M$1))*(Q$1-$M$1)+$M32 -> 8203.512 | R32: 8394.4 | S32: =(($W32-$R32)/($W$1-$R$1))*(S$1-$R$1)+$R32 -> 8527.268 | T32: =(($W32-$R32)/($W$1-$R$1))*(T$1-$R$1)+$R32 -> 8660.136 | U32: =(($W32-$R32)/($W$1-$R$1))*(U$1-$R$1)+$R32 -> 8793.004 | V32: =(($W32-$R32)/($W$1-$R$1))*(V$1-$R$1)+$R32 -> 8925.872 | W32: 9058.74 | X32: =(($AB32-$W32)/($AB$1-$W$1))*(X$1-$W$1)+$W32 -> 9140.152 | Y32: =(($AB32-$W32)/($AB$1-$W$1))*(Y$1-$W$1)+$W32 -> 9221.564 | Z32: =(($AB32-$W32)/($AB$1-$W$1))*(Z$1-$W$1)+$W32 -> 9302.976 | AA32: =(($AB32-$W32)/($AB$1-$W$1))*(AA$1-$W$1)+$W32 -> 9384.388 | AB32: 9465.8 | AC32: =(($AG32-$AB32)/($AG$1-$AB$1))*(AC$1-$AB$1)+$AB32 -> 9350.108 | AD32: =(($AG32-$AB32)/($AG$1-$AB$1))*(AD$1-$AB$1)+$AB32 -> 9234.416 | AE32: =(($AG32-$AB32)/($AG$1-$AB$1))*(AE$1-$AB$1)+$AB32 -> 9118.724 | AF32: =(($AG32-$AB32)/($AG$1-$AB$1))*(AF$1-$AB$1)+$AB32 -> 9003.032 | AG32: 8887.34 | AH32: =SUM(Tableau2[[#This Row],[2022]:[2050]]) -> 226600.82
A33: Electricity Networks | B33: Wire | C33: Copper | D33: SPS | E33: 4181.61 | F33: =(($H33-$E33)/($H$1-$E$1))*(F$1-$E$1)+$E33 -> 4314.0433 | G33: =(($H33-$E33)/($H$1-$E$1))*(G$1-$E$1)+$E33 -> 4446.4767 | H33: 4578.91 | I33: =(($M33-$H33)/($M$1-$H$1))*(I$1-$H$1)+$H33 -> 4965.178 | J33: =(($M33-$H33)/($M$1-$H$1))*(J$1-$H$1)+$H33 -> 5351.446 | K33: =(($M33-$H33)/($M$1-$H$1))*(K$1-$H$1)+$H33 -> 5737.714 | L33: =(($M33-$H33)/($M$1-$H$1))*(L$1-$H$1)+$H33 -> 6123.982 | M33: 6510.25 | N33: =(($R33-$M33)/($R$1-$M$1))*(N$1-$M$1)+$M33 -> 6510.366 | O33: =(($R33-$M33)/($R$1-$M$1))*(O$1-$M$1)+$M33 -> 6510.482 | P33: =(($R33-$M33)/($R$1-$M$1))*(P$1-$M$1)+$M33 -> 6510.598 | Q33: =(($R33-$M33)/($R$1-$M$1))*(Q$1-$M$1)+$M33 -> 6510.714 | R33: 6510.83 | S33: =(($W33-$R33)/($W$1-$R$1))*(S$1-$R$1)+$R33 -> 6525.144 | T33: =(($W33-$R33)/($W$1-$R$1))*(T$1-$R$1)+$R33 -> 6539.458 | U33: =(($W33-$R33)/($W$1-$R$1))*(U$1-$R$1)+$R33 -> 6553.772 | V33: =(($W33-$R33)/($W$1-$R$1))*(V$1-$R$1)+$R33 -> 6568.086 | W33: 6582.4 | X33: =(($AB33-$W33)/($AB$1-$W$1))*(X$1-$W$1)+$W33 -> 6688.606 | Y33: =(($AB33-$W33)/($AB$1-$W$1))*(Y$1-$W$1)+$W33 -> 6794.812 | Z33: =(($AB33-$W33)/($AB$1-$W$1))*(Z$1-$W$1)+$W33 -> 6901.018 | AA33: =(($AB33-$W33)/($AB$1-$W$1))*(AA$1-$W$1)+$W33 -> 7007.224 | AB33: 7113.43 | AC33: =(($AG33-$AB33)/($AG$1-$AB$1))*(AC$1-$AB$1)+$AB33 -> 7087.208 | AD33: =(($AG33-$AB33)/($AG$1-$AB$1))*(AD$1-$AB$1)+$AB33 -> 7060.986 | AE33: =(($AG33-$AB33)/($AG$1-$AB$1))*(AE$1-$AB$1)+$AB33 -> 7034.764 | AF33: =(($AG33-$AB33)/($AG$1-$AB$1))*(AF$1-$AB$1)+$AB33 -> 7008.542 | AG33: 6982.32 | AH33: =SUM(Tableau2[[#This Row],[2022]:[2050]]) -> 181210.37
A34: Solar PV | C34: Copper | D34: NZE | E34: 681.645 | F34: =(($H34-$E34)/($H$1-$E$1))*(F$1-$E$1)+$E34 -> 874.01667 | G34: =(($H34-$E34)/($H$1-$E$1))*(G$1-$E$1)+$E34 -> 1066.3883 | H34: 1258.76 | I34: =(($M34-$H34)/($M$1-$H$1))*(I$1-$H$1)+$H34 -> 1405.068 | J34: =(($M34-$H34)/($M$1-$H$1))*(J$1-$H$1)+$H34 -> 1551.376 | K34: =(($M34-$H34)/($M$1-$H$1))*(K$1-$H$1)+$H34 -> 1697.684 | L34: =(($M34-$H34)/($M$1-$H$1))*(L$1-$H$1)+$H34 -> 1843.992 | M34: 1990.3 | N34: =(($R34-$M34)/($R$1-$M$1))*(N$1-$M$1)+$M34 -> 2004.74 | O34: =(($R34-$M34)/($R$1-$M$1))*(O$1-$M$1)+$M34 -> 2019.18 | P34: =(($R34-$M34)/($R$1-$M$1))*(P$1-$M$1)+$M34 -> 2033.62 | Q34: =(($R34-$M34)/($R$1-$M$1))*(Q$1-$M$1)+$M34 -> 2048.06 | R34: 2062.5 | S34: =(($W34-$R34)/($W$1-$R$1))*(S$1-$R$1)+$R34 -> 2055.27 | T34: =(($W34-$R34)/($W$1-$R$1))*(T$1-$R$1)+$R34 -> 2048.04 | U34: =(($W34-$R34)/($W$1-$R$1))*(U$1-$R$1)+$R34 -> 2040.81 | V34: =(($W34-$R34)/($W$1-$R$1))*(V$1-$R$1)+$R34 -> 2033.58 | W34: 2026.35 | X34: =(($AB34-$W34)/($AB$1-$W$1))*(X$1-$W$1)+$W34 -> 1955.82 | Y34: =(($AB34-$W34)/($AB$1-$W$1))*(Y$1-$W$1)+$W34 -> 1885.29 | Z34: =(($AB34-$W34)/($AB$1-$W$1))*(Z$1-$W$1)+$W34 -> 1814.76 | AA34: =(($AB34-$W34)/($AB$1-$W$1))*(AA$1-$W$1)+$W34 -> 1744.23 | AB34: 1673.7 | AC34: =(($AG34-$AB34)/($AG$1-$AB$1))*(AC$1-$AB$1)+$AB34 -> 1714.916 | AD34: =(($AG34-$AB34)/($AG$1-$AB$1))*(AD$1-$AB$1)+$AB34 -> 1756.132 | AE34: =(($AG34-$AB34)/($AG$1-$AB$1))*(AE$1-$AB$1)+$AB34 -> 1797.348 | AF34: =(($AG34-$AB34)/($AG$1-$AB$1))*(AF$1-$AB$1)+$AB34 -> 1838.564 | AG34: 1879.78 | AH34: =SUM(Tableau2[[#This Row],[2022]:[2050]]) -> 50801.92
